Workbook

Sheet Dia 0
B2: AMOSTRA | D2: pH | E2: TURBIDEZ (NTU) | F2: CONDUTIVIDADE mS/cm | G2: COR | I2: DQO
G3: Medida | H3: Diluição | I3: Triplicata 1 | J3: Triplicata 2 | K3: Média | L3: Diluição | M3: Valor
B4: AI | C4: 0 | D4: 5.87 | E4: 0.86 | F4: 11.83 | G4: 0 | H4: =G4 -> 0 | I4: 0.006 | J4: 0.004 | K4: =AVERAGE(I4:J4) -> 0.005 | L4: =K4 -> 0.005 | M4: =(2349.6*L4) - 3.893 -> 7.855
C5: 25 | D5: 9.15 | E5: 56.2 | F5: 5.92 | G5: 312 | H5: =G5*5 -> 1560 | I5: 0.121 | J5: 0.137 | K5: =AVERAGE(I5:J5) -> 0.129 | L5: =K5*5 -> 0.645 | M5: =(2349.6*L5) - 3.893 -> 1511.599
C6: 50 | D6: 9.24 | E6: 106 | F6: 10.78 | G6: 298 | H6: =G6*10 -> 2980 | I6: 0.135 | J6: 0.122 | K6: =AVERAGE(I6:J6) -> 0.1285 | L6: =K6*10 -> 1.285 | M6: =(2349.6*L6) - 3.893 -> 3015.343
C7: 75 | D7: 9.26 | E7: 108 | F7: 15.2 | G7: 212 | H7: =G7*20 -> 4240 | I7: 0.083 | J7: 0.084 | K7: =AVERAGE(I7:J7) -> 0.0835 | L7: =K7*20 -> 1.67 | M7: =(2349.6*L7) - 3.893 -> 3919.939
C8: 100 | D8: 9.27 | E8: 152 | F8: 19.67 | G8: 289 | H8: =G8*20 -> 5780 | I8: 0.109 | J8: 0.112 | K8: =AVERAGE(I8:J8) -> 0.1105 | L8: =K8*20 -> 2.21 | M8: =(2349.6*L8) - 3.893 -> 5188.723
B10: A | C10: 0 | D10: 5.87 | E10: 0.86 | F10: 11.83 | G10: 0 | H10: =G10 -> 0 | I10: 0.006 | J10: 0.004 | K10: =AVERAGE(I10:J10) -> 0.005 | L10: =K10 -> 0.005 | M10: =(2349.6*L10) - 3.893 -> 7.855
C11: 25 | D11: 9.15 | E11: 56.2 | F11: 5.92 | G11: 312 | H11: =G11*5 -> 1560 | I11: 0.121 | J11: 0.137 | K11: =AVERAGE(I11:J11) -> 0.129 | L11: =K11*5 -> 0.645 | M11: =(2349.6*L11) - 3.893 -> 1511.599
C12: 50 | D12: 9.24 | E12: 106 | F12: 10.78 | G12: 298 | H12: =G12*10 -> 2980 | I12: 0.135 | J12: 0.122 | K12: =AVERAGE(I12:J12) -> 0.1285 | L12: =K12*10 -> 1.285 | M12: =(2349.6*L12) - 3.893 -> 3015.343
C13: 75 | D13: 9.26 | E13: 108 | F13: 15.2 | G13: 212 | H13: =G13*20 -> 4240 | I13: 0.083 | J13: 0.084 | K13: =AVERAGE(I13:J13) -> 0.0835 | L13: =K13*20 -> 1.67 | M13: =(2349.6*L13) - 3.893 -> 3919.939
C14: 100 | D14: 9.27 | E14: 152 | F14: 19.67 | G14: 289 | H14: =G14*20 -> 5780 | I14: 0.109 | J14: 0.112 | K14: =AVERAGE(I14:J14) -> 0.1105 | L14: =K14*20 -> 2.21 | M14: =(2349.6*L14) - 3.893 -> 5188.723
B16: BI | C16: 0 | D16: 5.87 | E16: 0.86 | F16: 11.83 | G16: 0 | H16: =G16 -> 0 | I16: 0.006 | J16: 0.004 | K16: =AVERAGE(I16:J16) -> 0.005 | L16: =K16 -> 0.005 | M16: =(2349.6*L16) - 3.893 -> 7.855
C17: 25 | D17: 8.33 | E17: 26.2 | F17: 7.48 | G17: 263 | H17: =G17*5 -> 1315 | I17: 0.136 | J17: 0.139 | K17: =AVERAGE(I17:J17) -> 0.1375 | L17: =K17*5 -> 0.6875 | M17: =(2349.6*L17) - 3.893 -> 1611.457
C18: 50 | D18: 8.31 | E18: 41.8 | F18: 13.65 | G18: 238 | H18: =G18*10 -> 2380 | I18: 0.121 | J18: 0.133 | K18: =AVERAGE(I18:J18) -> 0.127 | L18: =K18*10 -> 1.27 | M18: =(2349.6*L18) - 3.893 -> 2980.099
C19: 75 | D19: 8.34 | E19: 62.7 | F19: 19.62 | G19: 183 | H19: =G19*20 -> 3660 | I19: 0.1 | J19: 0.094 | K19: =AVERAGE(I19:J19) -> 0.097 | L19: =K19*20 -> 1.94 | M19: =(2349.6*L19) - 3.893 -> 4554.331
C20: 100 | D20: 8.21 | E20: 77.8 | F20: 24.94 | G20: 258 | H20: =G20*20 -> 5160 | I20: 0.125 | J20: 0.139 | K20: =AVERAGE(I20:J20) -> 0.132 | L20: =K20*20 -> 2.64 | M20: =(2349.6*L20) - 3.893 -> 6199.051
B22: B | C22: 0 | D22: 5.87 | E22: 0.86 | F22: 11.83 | G22: 0 | H22: =G22 -> 0 | I22: 0.006 | J22: 0.004 | K22: =AVERAGE(I22:J22) -> 0.005 | L22: =K22 -> 0.005 | M22: =(2349.6*L22) - 3.893 -> 7.855
C23: 25 | D23: 8.33 | E23: 26.2 | F23: 7.48 | G23: 263 | H23: =G23*5 -> 1315 | I23: 0.136 | J23: 0.139 | K23: =AVERAGE(I23:J23) -> 0.1375 | L23: =K23*5 -> 0.6875 | M23: =(2349.6*L23) - 3.893 -> 1611.457
C24: 50 | D24: 8.31 | E24: 41.8 | F24: 13.65 | G24: 238 | H24: =G24*10 -> 2380 | I24: 0.121 | J24: 0.133 | K24: =AVERAGE(I24:J24) -> 0.127 | L24: =K24*10 -> 1.27 | M24: =(2349.6*L24) - 3.893 -> 2980.099
C25: 75 | D25: 8.34 | E25: 62.7 | F25: 19.62 | G25: 183 | H25: =G25*20 -> 3660 | I25: 0.1 | J25: 0.094 | K25: =AVERAGE(I25:J25) -> 0.097 | L25: =K25*20 -> 1.94 | M25: =(2349.6*L25) - 3.893 -> 4554.331
C26: 100 | D26: 8.21 | E26: 77.8 | F26: 24.94 | G26: 258 | H26: =G26*20 -> 5160 | I26: 0.125 | J26: 0.139 | K26: =AVERAGE(I26:J26) -> 0.132 | L26: =K26*20 -> 2.64 | M26: =(2349.6*L26) - 3.893 -> 6199.051

Sheet Dados prontos dia 0
A1: μS/cm
B2: AMOSTRA | D2: pH | E2: TURBIDEZ (NTU) | F2: CONDUTIVIDADE mS/cm | G2: COR | H2: DQO
B4: AI | C4: 0 | D4: ='Dia 0'!D4 -> 5.87 | E4: ='Dia 0'!E4 -> 0.86 | F4: ='Dia 0'!F4 -> 11.83 | G4: ='Dia 0'!H4 -> 0 | H4: ='Dia 0'!$M4 -> 7.855
C5: 25 | D5: ='Dia 0'!D5 -> 9.15 | E5: ='Dia 0'!E5 -> 56.2 | F5: ='Dia 0'!F5 -> 5.92 | G5: ='Dia 0'!H5 -> 1560 | H5: ='Dia 0'!$M5 -> 1511.599
C6: 50 | D6: ='Dia 0'!D6 -> 9.24 | E6: ='Dia 0'!E6 -> 106 | F6: ='Dia 0'!F6 -> 10.78 | G6: ='Dia 0'!H6 -> 2980 | H6: ='Dia 0'!$M6 -> 3015.343
C7: 75 | D7: ='Dia 0'!D7 -> 9.26 | E7: ='Dia 0'!E7 -> 108 | F7: ='Dia 0'!F7 -> 15.2 | G7: ='Dia 0'!H7 -> 4240 | H7: ='Dia 0'!$M7 -> 3919.939
C8: 100 | D8: ='Dia 0'!D8 -> 9.27 | E8: ='Dia 0'!E8 -> 152 | F8: ='Dia 0'!F8 -> 19.67 | G8: ='Dia 0'!H8 -> 5780 | H8: ='Dia 0'!$M8 -> 5188.723
B10: A | C10: 0 | D10: ='Dia 0'!D10 -> 5.87 | E10: ='Dia 0'!E10 -> 0.86 | F10: ='Dia 0'!F10 -> 11.83 | G10: ='Dia 0'!H10 -> 0 | H10: ='Dia 0'!$M10 -> 7.855
C11: 25 | D11: ='Dia 0'!D11 -> 9.15 | E11: ='Dia 0'!E11 -> 56.2 | F11: ='Dia 0'!F11 -> 5.92 | G11: ='Dia 0'!H11 -> 1560 | H11: ='Dia 0'!$M11 -> 1511.599
C12: 50 | D12: ='Dia 0'!D12 -> 9.24 | E12: ='Dia 0'!E12 -> 106 | F12: ='Dia 0'!F12 -> 10.78 | G12: ='Dia 0'!H12 -> 2980 | H12: ='Dia 0'!$M12 -> 3015.343
C13: 75 | D13: ='Dia 0'!D13 -> 9.26 | E13: ='Dia 0'!E13 -> 108 | F13: ='Dia 0'!F13 -> 15.2 | G13: ='Dia 0'!H13 -> 4240 | H13: ='Dia 0'!$M13 -> 3919.939
C14: 100 | D14: ='Dia 0'!D14 -> 9.27 | E14: ='Dia 0'!E14 -> 152 | F14: ='Dia 0'!F14 -> 19.67 | G14: ='Dia 0'!H14 -> 5780 | H14: ='Dia 0'!$M14 -> 5188.723
B16: I | C16: 0 | D16: ='Dia 0'!D16 -> 5.87 | E16: ='Dia 0'!E16 -> 0.86 | F16: ='Dia 0'!F16 -> 11.83 | G16: ='Dia 0'!H16 -> 0 | H16: ='Dia 0'!$M18 -> 2980.099
C17: 25 | D17: ='Dia 0'!D17 -> 8.33 | E17: ='Dia 0'!E17 -> 26.2 | F17: ='Dia 0'!F17 -> 7.48 | G17: ='Dia 0'!H17 -> 1315 | H17: ='Dia 0'!$M19 -> 4554.331
C18: 50 | D18: ='Dia 0'!D18 -> 8.31 | E18: ='Dia 0'!E18 -> 41.8 | F18: ='Dia 0'!F18 -> 13.65 | G18: ='Dia 0'!H18 -> 2380 | H18: ='Dia 0'!$M20 -> 6199.051
C19: 75 | D19: ='Dia 0'!D19 -> 8.34 | E19: ='Dia 0'!E19 -> 62.7 | F19: ='Dia 0'!F19 -> 19.62 | G19: ='Dia 0'!H19 -> 3660 | H19: ='Dia 0'!$M21
C20: 100 | D20: ='Dia 0'!D20 -> 8.21 | E20: ='Dia 0'!E20 -> 77.8 | F20: ='Dia 0'!F20 -> 24.94 | G20: ='Dia 0'!H20 -> 5160 | H20: ='Dia 0'!$M22 -> 7.855
B22: X | C22: 0 | D22: ='Dia 0'!D22 -> 5.87 | E22: ='Dia 0'!E22 -> 0.86 | F22: ='Dia 0'!F22 -> 11.83 | G22: ='Dia 0'!H22 -> 0 | H22: ='Dia 0'!$M26 -> 6199.051
C23: 25 | D23: ='Dia 0'!D23 -> 8.33 | E23: ='Dia 0'!E23 -> 26.2 | F23: ='Dia 0'!F23 -> 7.48 | G23: ='Dia 0'!H23 -> 1315 | H23: ='Dia 0'!$M27
C24: 50 | D24: ='Dia 0'!D24 -> 8.31 | E24: ='Dia 0'!E24 -> 41.8 | F24: ='Dia 0'!F24 -> 13.65 | G24: ='Dia 0'!H24 -> 2380 | H24: ='Dia 0'!$M28
C25: 75 | D25: ='Dia 0'!D25 -> 8.34 | E25: ='Dia 0'!E25 -> 62.7 | F25: ='Dia 0'!F25 -> 19.62 | G25: ='Dia 0'!H25 -> 3660 | H25: ='Dia 0'!$M29
C26: 100 | D26: ='Dia 0'!D26 -> 8.21 | E26: ='Dia 0'!E26 -> 77.8 | F26: ='Dia 0'!F26 -> 24.94 | G26: ='Dia 0'!H26 -> 5160 | H26: ='Dia 0'!$M30

Sheet Dia 7
A1: μS/cm
B2: AMOSTRA | D2: pH | E2: TURBIDEZ (NTU) | F2: CONDUTIVIDADE mS/cm | G2: COR | I2: DQO
G3: Medida | H3: Diluição | I3: Duplicata 1 | J3: Duplicata 2 | K3: Média | L3: Diluição | M3: Valor
B4: AI | C4: 0 | D4: 8.85 | E4: 0.061 | F4: 37.4 | G4: 51 | H4: =G4 -> 51 | I4: 0.038 | J4: 0.038 | K4: =AVERAGE(I4:J4) -> 0.038 | L4: =K4 -> 0.038 | M4: =(2349.6*L4) - 3.893 -> 85.3918
C5: 25 | D5: 9.25 | E5: 65.5 | F5: 4.5 | G5: 137 | H5: =G5*5 -> 685 | I5: 0.053 | J5: 0.053 | K5: =AVERAGE(I5:J5) -> 0.053 | L5: =K5*5 -> 0.265 | M5: =(2349.6*L5) - 3.893 -> 618.751
C6: 50 | D6: 9.37 | E6: 107 | F6: 8.48 | G6: 278 | H6: =G6*10 -> 2780 | I6: 0.098 | J6: 0.104 | K6: =AVERAGE(I6:J6) -> 0.101 | L6: =K6*10 -> 1.01 | M6: =(2349.6*L6) - 3.893 -> 2369.203
C7: 75 | D7: 9.44 | E7: 143 | F7: 13.36 | G7: 193 | H7: =G7*10 -> 1930 | I7: 0.083 | J7: 0.083 | K7: =AVERAGE(I7:J7) -> 0.083 | L7: =K7*10 -> 0.83 | M7: =(2349.6*L7) - 3.893 -> 1946.275
C8: 100 | D8: 9.44 | E8: 156 | F8: 17.64 | G8: 255 | H8: =G8*10 -> 2550 | I8: 0.108 | J8: 0.108 | K8: =AVERAGE(I8:J8) -> 0.108 | L8: =K8*10 -> 1.08 | M8: =(2349.6*L8) - 3.893 -> 2533.675
B10: A | C10: 0 | D10: 8.47 | E10: 0 | F10: 20.2 | G10: 2 | H10: =G10 -> 2 | I10: 0.005 | J10: 0.011 | K10: =AVERAGE(I10:J10) -> 0.008 | L10: =K10 -> 0.008 | M10: =(2349.6*L10) - 3.893 -> 14.9038
C11: 25 | D11: 9.26 | E11: 49.8 | F11: 4.37 | G11: 99 | H11: =G11*5 -> 495 | I11: 0.049 | J11: 0.052 | K11: =AVERAGE(I11:J11) -> 0.0505 | L11: =K11*5 -> 0.2525 | M11: =(2349.6*L11) - 3.893 -> 589.381
C12: 50 | D12: 9.38 | E12: 86.6 | F12: 8.41 | G12: 230 | H12: =G12*10 -> 2300 | I12: 0.096 | J12: 0.098 | K12: =AVERAGE(I12:J12) -> 0.097 | L12: =K12*10 -> 0.97 | M12: =(2349.6*L12) - 3.893 -> 2275.219
C13: 75 | D13: 9.44 | E13: 136 | F13: 13.03 | G13: 181 | H13: =G13*10 -> 1810 | I13: 0.077 | J13: 0.081 | K13: =AVERAGE(I13:J13) -> 0.079 | L13: =K13*10 -> 0.79 | M13: =(2349.6*L13) - 3.893 -> 1852.291
C14: 100 | D14: 9.46 | E14: 164 | F14: 17.22 | G14: 254 | H14: =G14*10 -> 2540 | I14: 0.121 | J14: 0.104 | K14: =AVERAGE(I14:J14) -> 0.1125 | L14: =K14*10 -> 1.125 | M14: =(2349.6*L14) - 3.893 -> 2639.407
B16: BI | C16: 0 | D16: 8.85 | E16: 0.61 | F16: 37.4 | G16: 51 | H16: =G16 -> 51 | I16: 0.038 | J16: 0.038 | K16: =AVERAGE(I16:J16) -> 0.038 | L16: =K16 -> 0.038 | M16: =(2349.6*L16) - 3.893 -> 85.3918
C17: 25 | D17: 9.22 | E17: 45.1 | F17: 4.95 | G17: 129 | H17: =G17*5 -> 645 | I17: 0.054 | J17: 0.059 | K17: =AVERAGE(I17:J17) -> 0.0565 | L17: =K17*5 -> 0.2825 | M17: =(2349.6*L17) - 3.893 -> 659.869
C18: 50 | D18: 9.34 | E18: 87.7 | F18: 9.85 | G18: 291 | H18: =G18*10 -> 2910 | I18: 0.117 | J18: 0.103 | K18: =AVERAGE(I18:J18) -> 0.11 | L18: =K18*10 -> 1.1 | M18: =(2349.6*L18) - 3.893 -> 2580.667
C19: 75 | D19: 9.3 | E19: 89.3 | F19: 14.8 | G19: 193 | H19: =G19*10 -> 1930 | I19: 0.079 | J19: 0.082 | K19: =AVERAGE(I19:J19) -> 0.0805 | L19: =K19*10 -> 0.805 | M19: =(2349.6*L19) - 3.893 -> 1887.535
C20: 100 | D20: 9.33 | E20: 104 | F20: 18.21 | G20: 242 | H20: =G20*20 -> 4840 | I20: 0.107 | J20: 0.1 | K20: =AVERAGE(I20:J20) -> 0.1035 | L20: =K20*10 -> 1.035 | M20: =(2349.6*L20) - 3.893 -> 2427.943
B22: B | C22: 0 | D22: 8.47 | E22: 0 | F22: 20.2 | G22: 2 | H22: =G22 -> 2 | I22: 0.005 | J22: 0.011 | K22: =AVERAGE(I22:J22) -> 0.008 | L22: =K22 -> 0.008 | M22: =(2349.6*L22) - 3.893 -> 14.9038
C23: 25 | D23: 9.29 | E23: 33.3 | F23: 5.06 | G23: 119 | H23: =G23*5 -> 595 | I23: 0.059 | J23: 0.054 | K23: =AVERAGE(I23:J23) -> 0.0565 | L23: =K23*5 -> 0.2825 | M23: =(2349.6*L23) - 3.893 -> 659.869
C24: 50 | D24: 9.34 | E24: 60.3 | F24: 9.91 | G24: 259 | H24: =G24*10 -> 2590 | I24: 0.117 | J24: 0.103 | K24: =AVERAGE(I24:J24) -> 0.11 | L24: =K24*10 -> 1.1 | M24: =(2349.6*L24) - 3.893 -> 2580.667
C25: 75 | D25: 9.36 | E25: 79.3 | F25: 14.52 | G25: 189 | H25: =G25*10 -> 1890 | I25: 0.079 | J25: 0.082 | K25: =AVERAGE(I25:J25) -> 0.0805 | L25: =K25*10 -> 0.805 | M25: =(2349.6*L25) - 3.893 -> 1887.535
C26: 100 | D26: 9.3 | E26: 95.5 | F26: 17.74 | G26: 246 | H26: =G26*10 -> 2460 | I26: 0.107 | J26: 0.1 | K26: =AVERAGE(I26:J26) -> 0.1035 | L26: =K26*10 -> 1.035 | M26: =(2349.6*L26) - 3.893 -> 2427.943

Sheet Dados prontos dia 7
A1: μS/cm
B2: AMOSTRA | D2: pH | E2: TURBIDEZ (NTU) | F2: CONDUTIVIDADE mS/cm | G2: COR | H2: DQO
B4: AI | C4: 0 | D4: ='Dia 7'!D4 -> 8.85 | E4: ='Dia 7'!E4 -> 0.061 | F4: ='Dia 7'!F4 -> 37.4 | G4: ='Dia 7'!H4 -> 51 | H4: ='Dia 7'!M4 -> 85.3918
C5: 25 | D5: ='Dia 7'!D5 -> 9.25 | E5: ='Dia 7'!E5 -> 65.5 | F5: ='Dia 7'!F5 -> 4.5 | G5: ='Dia 7'!H5 -> 685 | H5: ='Dia 7'!M5 -> 618.751
C6: 50 | D6: ='Dia 7'!D6 -> 9.37 | E6: ='Dia 7'!E6 -> 107 | F6: ='Dia 7'!F6 -> 8.48 | G6: ='Dia 7'!H6 -> 2780 | H6: ='Dia 7'!M6 -> 2369.203
C7: 75 | D7: ='Dia 7'!D7 -> 9.44 | E7: ='Dia 7'!E7 -> 143 | F7: ='Dia 7'!F7 -> 13.36 | G7: ='Dia 7'!H7 -> 1930 | H7: ='Dia 7'!M7 -> 1946.275
C8: 100 | D8: ='Dia 7'!D8 -> 9.44 | E8: ='Dia 7'!E8 -> 156 | F8: ='Dia 7'!F8 -> 17.64 | G8: ='Dia 7'!H8 -> 2550 | H8: ='Dia 7'!M8 -> 2533.675
B10: A | C10: 0 | D10: ='Dia 7'!D10 -> 8.47 | E10: ='Dia 7'!E10 -> 0 | F10: ='Dia 7'!F10 -> 20.2 | G10: ='Dia 7'!H10 -> 2 | H10: ='Dia 7'!M10 -> 14.9038
C11: 25 | D11: ='Dia 7'!D11 -> 9.26 | E11: ='Dia 7'!E11 -> 49.8 | F11: ='Dia 7'!F11 -> 4.37 | G11: ='Dia 7'!H11 -> 495 | H11: ='Dia 7'!M11 -> 589.381
C12: 50 | D12: ='Dia 7'!D12 -> 9.38 | E12: ='Dia 7'!E12 -> 86.6 | F12: ='Dia 7'!F12 -> 8.41 | G12: ='Dia 7'!H12 -> 2300 | H12: ='Dia 7'!M12 -> 2275.219
C13: 75 | D13: ='Dia 7'!D13 -> 9.44 | E13: ='Dia 7'!E13 -> 136 | F13: ='Dia 7'!F13 -> 13.03 | G13: ='Dia 7'!H13 -> 1810 | H13: ='Dia 7'!M13 -> 1852.291
C14: 100 | D14: ='Dia 7'!D14 -> 9.46 | E14: ='Dia 7'!E14 -> 164 | F14: ='Dia 7'!F14 -> 17.22 | G14: ='Dia 7'!H14 -> 2540 | H14: ='Dia 7'!M14 -> 2639.407
B16: I | C16: 0 | D16: ='Dia 7'!D16 -> 8.85 | E16: ='Dia 7'!E16 -> 0.61 | F16: ='Dia 7'!F16 -> 37.4 | G16: ='Dia 7'!H16 -> 51 | H16: ='Dia 7'!M16 -> 85.3918
C17: 25 | D17: ='Dia 7'!D17 -> 9.22 | E17: ='Dia 7'!E17 -> 45.1 | F17: ='Dia 7'!F17 -> 4.95 | G17: ='Dia 7'!H17 -> 645 | H17: ='Dia 7'!M17 -> 659.869
C18: 50 | D18: ='Dia 7'!D18 -> 9.34 | E18: ='Dia 7'!E18 -> 87.7 | F18: ='Dia 7'!F18 -> 9.85 | G18: ='Dia 7'!H18 -> 2910 | H18: ='Dia 7'!M18 -> 2580.667
C19: 75 | D19: ='Dia 7'!D19 -> 9.3 | E19: ='Dia 7'!E19 -> 89.3 | F19: ='Dia 7'!F19 -> 14.8 | G19: ='Dia 7'!H19 -> 1930 | H19: ='Dia 7'!M19 -> 1887.535
C20: 100 | D20: ='Dia 7'!D20 -> 9.33 | E20: ='Dia 7'!E20 -> 104 | F20: ='Dia 7'!F20 -> 18.21 | G20: ='Dia 7'!H20 -> 4840 | H20: ='Dia 7'!M20 -> 2427.943
B22: X | C22: 0 | D22: ='Dia 7'!D22 -> 8.47 | E22: ='Dia 7'!E22 -> 0 | F22: ='Dia 7'!F22 -> 20.2 | G22: ='Dia 7'!H22 -> 2 | H22: ='Dia 7'!M22 -> 14.9038
C23: 25 | D23: ='Dia 7'!D23 -> 9.29 | E23: ='Dia 7'!E23 -> 33.3 | F23: ='Dia 7'!F23 -> 5.06 | G23: ='Dia 7'!H23 -> 595 | H23: ='Dia 7'!M23 -> 659.869
C24: 50 | D24: ='Dia 7'!D24 -> 9.34 | E24: ='Dia 7'!E24 -> 60.3 | F24: ='Dia 7'!F24 -> 9.91 | G24: ='Dia 7'!H24 -> 2590 | H24: ='Dia 7'!M24 -> 2580.667
C25: 75 | D25: ='Dia 7'!D25 -> 9.36 | E25: ='Dia 7'!E25 -> 79.3 | F25: ='Dia 7'!F25 -> 14.52 | G25: ='Dia 7'!H25 -> 1890 | H25: ='Dia 7'!M25 -> 1887.535
C26: 100 | D26: ='Dia 7'!D26 -> 9.3 | E26: ='Dia 7'!E26 -> 95.5 | F26: ='Dia 7'!F26 -> 17.74 | G26: ='Dia 7'!H26 -> 2460 | H26: ='Dia 7'!M26 -> 2427.943

Sheet Dia 14
A1: μS/cm
B2: AMOSTRA | D2: pH | E2: TURBIDEZ (NTU) | F2: CONDUTIVIDADE mS/cm | G2: COR | I2: DQO
G3: Medida | H3: Diluição | I3: Duplicata 1 | J3: Duplicata 2 | K3: Média | L3: Diluição | M3: Valor
B4: AI | C4: 0 | D4: 5.83 | E4: 2.07 | F4: 31.7 | G4: 39 | H4: =G4 -> 39 | I4: 0.023 | J4: 0.023 | K4: =AVERAGE(I4:J4) -> 0.023 | L4: =K4 -> 0.023 | M4: =(2349.6*L4) - 3.893 -> 50.1478
C5: 25 | D5: 8.65 | E5: 66.7 | F5: 4.01 | G5: 134 | H5: =G5*10 -> 1340 | I5: 0.054 | J5: 0.058 | K5: =AVERAGE(I5:J5) -> 0.056 | L5: =K5*10 -> 0.56 | M5: =(2349.6*L5) - 3.893 -> 1311.883
C6: 50 | D6: 8.8 | E6: 111 | F6: 7.86 | G6: 280 | H6: =G6*10 -> 2800 | I6: 0.106 | J6: 0.108 | K6: =AVERAGE(I6:J6) -> 0.107 | L6: =K6*10 -> 1.07 | M6: =(2349.6*L6) - 3.893 -> 2510.179
C7: 75 | D7: 8.88 | E7: 154 | F7: 12.28 | G7: 193 | H7: =G7*20 -> 3860 | I7: 0.087 | J7: 0.093 | K7: =AVERAGE(I7:J7) -> 0.09 | L7: =K7*20 -> 1.8 | M7: =(2349.6*L7) - 3.893 -> 4225.387
C8: 100 | D8: 8.89 | E8: 168 | F8: 16.08 | G8: 263 | H8: =G8*20 -> 5260 | I8: 0.124 | J8: 0.12 | K8: =AVERAGE(I8:J8) -> 0.122 | L8: =K8*20 -> 2.44 | M8: =(2349.6*L8) - 3.893 -> 5729.131
B10: A | C10: 0 | D10: 7.93 | E10: 1.97 | F10: 37.1 | G10: 0 | H10: =G10 -> 0 | I10: 0.015 | J10: 0.006 | K10: =AVERAGE(I10:J10) -> 0.0105 | L10: =K10 -> 0.0105 | M10: =(2349.6*L10) - 3.893 -> 20.7778
C11: 25 | D11: 8.65 | E11: 53.5 | F11: 4.06 | G11: 99 | H11: =G11*10 -> 990 | I11: 0.051 | J11: 0.05 | K11: =AVERAGE(I11:J11) -> 0.0505 | L11: =K11*10 -> 0.505 | M11: =(2349.6*L11) - 3.893 -> 1182.655
C12: 50 | D12: 8.75 | E12: 100 | F12: 7.91 | G12: 254 | H12: =G12*10 -> 2540 | I12: 0.096 | J12: 0.102 | K12: =AVERAGE(I12:J12) -> 0.099 | L12: =K12*10 -> 0.99 | M12: =(2349.6*L12) - 3.893 -> 2322.211
C13: 75 | D13: 8.73 | E13: 158 | F13: 12.07 | G13: 201 | H13: =G13*20 -> 4020 | I13: 0.086 | J13: 0.079 | K13: =AVERAGE(I13:J13) -> 0.0825 | L13: =K13*20 -> 1.65 | M13: =(2349.6*L13) - 3.893 -> 3872.947
C14: 100 | D14: 8.9 | E14: 183 | F14: 15.84 | G14: 252 | H14: =G14*20 -> 5040 | I14: 0.105 | J14: 0.104 | K14: =AVERAGE(I14:J14) -> 0.1045 | L14: =K14*20 -> 2.09 | M14: =(2349.6*L14) - 3.893 -> 4906.771
B16: BI | C16: 0 | D16: 8.09 | E16: 2.96 | F16: 38.9 | G16: 40 | H16: =G16 -> 40 | I16: 0.022 | J16: 0.024 | K16: =AVERAGE(I16:J16) -> 0.023 | L16: =K16 -> 0.023 | M16: =(2349.6*L16) - 3.893 -> 50.1478
C17: 25 | D17: 8.66 | E17: 30.4 | F17: 4.44 | G17: 133 | H17: =G17*10 -> 1330 | I17: 0.049 | J17: 0.047 | K17: =AVERAGE(I17:J17) -> 0.048 | L17: =K17*10 -> 0.48 | M17: =(2349.6*L17) - 3.893 -> 1123.915
C18: 50 | D18: 8.72 | E18: 55.2 | F18: 8.74 | G18: 274 | H18: =G18*10 -> 2740 | I18: 0.101 | J18: 0.1 | K18: =AVERAGE(I18:J18) -> 0.1005 | L18: =K18*10 -> 1.005 | M18: =(2349.6*L18) - 3.893 -> 2357.455
C19: 75 | D19: 8.75 | E19: 88.3 | F19: 13.29 | G19: 206 | H19: =G19*20 -> 4120 | I19: 0.08 | J19: 0.087 | K19: =AVERAGE(I19:J19) -> 0.0835 | L19: =K19*20 -> 1.67 | M19: =(2349.6*L19) - 3.893 -> 3919.939
C20: 100 | D20: 8.78 | E20: 108 | F20: 16.72 | G20: 269 | H20: =G20*20 -> 5380 | I20: 0.111 | J20: 0.109 | K20: =AVERAGE(I20:J20) -> 0.11 | L20: =K20*20 -> 2.2 | M20: =(2349.6*L20) - 3.893 -> 5165.227
B22: B | C22: 0 | D22: 8.04 | E22: 1.62 | F22: 22.18 | G22: 1 | H22: =G22 -> 1 | I22: 0.012 | J22: 0.013 | K22: =AVERAGE(I22:J22) -> 0.0125 | L22: =K22 -> 0.0125 | M22: =(2349.6*L22) - 3.893 -> 25.477
C23: 25 | D23: 8.72 | E23: 30.8 | F23: 4.63 | G23: 133 | H23: =G23*10 -> 1330 | I23: 0.046 | J23: 0.071 | K23: =AVERAGE(I23:J23) -> 0.0585 | L23: =K23*10 -> 0.585 | M23: =(2349.6*L23) - 3.893 -> 1370.623
C24: 50 | D24: 8.79 | E24: 63.5 | F24: 8.91 | G24: 274 | H24: =G24*10 -> 2740 | I24: 0.104 | J24: 0.116 | K24: =AVERAGE(I24:J24) -> 0.11 | L24: =K24*10 -> 1.1 | M24: =(2349.6*L24) - 3.893 -> 2580.667
C25: 75 | D25: 8.8 | E25: 82.7 | F25: 13.3 | G25: 206 | H25: =G25*20 -> 4120 | I25: 0.133 | J25: 0.089 | K25: =AVERAGE(I25:J25) -> 0.111 | L25: =K25*20 -> 2.22 | M25: =(2349.6*L25) - 3.893 -> 5212.219
C26: 100 | D26: 8.76 | E26: 106 | F26: 16.7 | G26: 269 | H26: =G26*20 -> 5380 | I26: 0.119 | J26: 0.108 | K26: =AVERAGE(I26:J26) -> 0.1135 | L26: =K26*20 -> 2.27 | M26: =(2349.6*L26) - 3.893 -> 5329.699

Sheet Dados prontos dia 14
A1: μS/cm
B2: AMOSTRA | D2: pH | E2: TURBIDEZ (NTU) | F2: CONDUTIVIDADE mS/cm | G2: COR | H2: DQO
B4: AI | C4: 0 | D4: ='Dia 14'!D4 -> 5.83 | E4: ='Dia 14'!E4 -> 2.07 | F4: ='Dia 14'!F4 -> 31.7 | G4: ='Dia 14'!H4 -> 39 | H4: ='Dia 14'!M4 -> 50.1478
C5: 25 | D5: ='Dia 14'!D5 -> 8.65 | E5: ='Dia 14'!E5 -> 66.7 | F5: ='Dia 14'!F5 -> 4.01 | G5: ='Dia 14'!H5 -> 1340 | H5: ='Dia 14'!M5 -> 1311.883
C6: 50 | D6: ='Dia 14'!D6 -> 8.8 | E6: ='Dia 14'!E6 -> 111 | F6: ='Dia 14'!F6 -> 7.86 | G6: ='Dia 14'!H6 -> 2800 | H6: ='Dia 14'!M6 -> 2510.179
C7: 75 | D7: ='Dia 14'!D7 -> 8.88 | E7: ='Dia 14'!E7 -> 154 | F7: ='Dia 14'!F7 -> 12.28 | G7: ='Dia 14'!H7 -> 3860 | H7: ='Dia 14'!M7 -> 4225.387
C8: 100 | D8: ='Dia 14'!D8 -> 8.89 | E8: ='Dia 14'!E8 -> 168 | F8: ='Dia 14'!F8 -> 16.08 | G8: ='Dia 14'!H8 -> 5260 | H8: ='Dia 14'!M8 -> 5729.131
B10: A | C10: 0 | D10: ='Dia 14'!D10 -> 7.93 | E10: ='Dia 14'!E10 -> 1.97 | F10: ='Dia 14'!F10 -> 37.1 | G10: ='Dia 14'!H10 -> 0 | H10: ='Dia 14'!M10 -> 20.7778
C11: 25 | D11: ='Dia 14'!D11 -> 8.65 | E11: ='Dia 14'!E11 -> 53.5 | F11: ='Dia 14'!F11 -> 4.06 | G11: ='Dia 14'!H11 -> 990 | H11: ='Dia 14'!M11 -> 1182.655
C12: 50 | D12: ='Dia 14'!D12 -> 8.75 | E12: ='Dia 14'!E12 -> 100 | F12: ='Dia 14'!F12 -> 7.91 | G12: ='Dia 14'!H12 -> 2540 | H12: ='Dia 14'!M12 -> 2322.211
C13: 75 | D13: ='Dia 14'!D13 -> 8.73 | E13: ='Dia 14'!E13 -> 158 | F13: ='Dia 14'!F13 -> 12.07 | G13: ='Dia 14'!H13 -> 4020 | H13: ='Dia 14'!M13 -> 3872.947
C14: 100 | D14: ='Dia 14'!D14 -> 8.9 | E14: ='Dia 14'!E14 -> 183 | F14: ='Dia 14'!F14 -> 15.84 | G14: ='Dia 14'!H14 -> 5040 | H14: ='Dia 14'!M14 -> 4906.771
B16: I | C16: 0 | D16: ='Dia 14'!D16 -> 8.09 | E16: ='Dia 14'!E16 -> 2.96 | F16: ='Dia 14'!F16 -> 38.9 | G16: ='Dia 14'!H16 -> 40 | H16: ='Dia 14'!M16 -> 50.1478
C17: 25 | D17: ='Dia 14'!D17 -> 8.66 | E17: ='Dia 14'!E17 -> 30.4 | F17: ='Dia 14'!F17 -> 4.44 | G17: ='Dia 14'!H17 -> 1330 | H17: ='Dia 14'!M17 -> 1123.915
C18: 50 | D18: ='Dia 14'!D18 -> 8.72 | E18: ='Dia 14'!E18 -> 55.2 | F18: ='Dia 14'!F18 -> 8.74 | G18: ='Dia 14'!H18 -> 2740 | H18: ='Dia 14'!M18 -> 2357.455
C19: 75 | D19: ='Dia 14'!D19 -> 8.75 | E19: ='Dia 14'!E19 -> 88.3 | F19: ='Dia 14'!F19 -> 13.29 | G19: ='Dia 14'!H19 -> 4120 | H19: ='Dia 14'!M19 -> 3919.939
C20: 100 | D20: ='Dia 14'!D20 -> 8.78 | E20: ='Dia 14'!E20 -> 108 | F20: ='Dia 14'!F20 -> 16.72 | G20: ='Dia 14'!H20 -> 5380 | H20: ='Dia 14'!M20 -> 5165.227
B22: X | C22: 0 | D22: ='Dia 14'!D22 -> 8.04 | E22: ='Dia 14'!E22 -> 1.62 | F22: ='Dia 14'!F22 -> 22.18 | G22: ='Dia 14'!H22 -> 1 | H22: ='Dia 14'!M22 -> 25.477
C23: 25 | D23: ='Dia 14'!D23 -> 8.72 | E23: ='Dia 14'!E23 -> 30.8 | F23: ='Dia 14'!F23 -> 4.63 | G23: ='Dia 14'!H23 -> 1330 | H23: ='Dia 14'!M23 -> 1370.623
C24: 50 | D24: ='Dia 14'!D24 -> 8.79 | E24: ='Dia 14'!E24 -> 63.5 | F24: ='Dia 14'!F24 -> 8.91 | G24: ='Dia 14'!H24 -> 2740 | H24: ='Dia 14'!M24 -> 2580.667
C25: 75 | D25: ='Dia 14'!D25 -> 8.8 | E25: ='Dia 14'!E25 -> 82.7 | F25: ='Dia 14'!F25 -> 13.3 | G25: ='Dia 14'!H25 -> 4120 | H25: ='Dia 14'!M25 -> 5212.219
C26: 100 | D26: ='Dia 14'!D26 -> 8.76 | E26: ='Dia 14'!E26 -> 106 | F26: ='Dia 14'!F26 -> 16.7 | G26: ='Dia 14'!H26 -> 5380 | H26: ='Dia 14'!M26 -> 5329.699

Sheet PROCESSAMENTO
B2: AMOSTRA | D2: Dia 0 | E2: Dia 7 | F2: Dia 14 | G2: Redução (%) | H2: Dia 0 | I2: Dia 7 | J2: Dia 14 | K2: Redução (%) | L2: Dia 0 | M2: Dia 7 | N2: Dia 14 | O2: Redução (%) | P2: Dia 0 | Q2: Dia 7 | R2: Dia 14 | S2: Redução (%) | T2: Dia 0 | U2: Dia 7 | V2: Dia 14 | W2: Degradação DQO (%)
D3: pH | H3: TURBIDEZ (NTU) | L3: CONDUTIVIDADE mS/cm | P3: COR | T3: DQO
B5: AI | C5: 0 | D5: ='Dia 0'!D4 -> 5.87 | E5: ='Dia 7'!D4 -> 8.85 | F5: ='Dia 14'!D4 -> 5.83 | G5: =((D5-F5)/D5)*100 -> 0.68143101 | H5: ='Dia 0'!E4 -> 0.86 | I5: ='Dia 7'!E4 -> 0.061 | J5: ='Dia 14'!E4 -> 2.07 | K5: =((H5-J5)/H5)*100 -> -140.69767 | L5: ='Dia 0'!F4 -> 11.83 | M5: ='Dia 7'!F4 -> 37.4 | N5: ='Dia 14'!F4 -> 31.7 | O5: =((L5-N5)/L5)*100 -> -167.96281 | P5: ='Dia 0'!H4 -> 0 | Q5: ='Dia 7'!H4 -> 51 | R5: ='Dia 14'!H4 -> 39 | S5: =((P5-R5)/P5)*100 -> #DIV/0! | T5: ='Dia 0'!M4 -> 7.855 | U5: ='Dia 7'!M4 -> 85.3918 | V5: ='Dia 14'!M4 -> 50.1478 | W5: =((T5-V5)/T5)*100 -> -538.41884
C6: 25 | D6: ='Dia 0'!D5 -> 9.15 | E6: ='Dia 7'!D5 -> 9.25 | F6: ='Dia 14'!D5 -> 8.65 | G6: =((D6-F6)/D6)*100 -> 5.4644809 | H6: ='Dia 0'!E5 -> 56.2 | I6: ='Dia 7'!E5 -> 65.5 | J6: ='Dia 14'!E5 -> 66.7 | K6: =((H6-J6)/H6)*100 -> -18.683274 | L6: ='Dia 0'!F5 -> 5.92 | M6: ='Dia 7'!F5 -> 4.5 | N6: ='Dia 14'!F5 -> 4.01 | O6: =((L6-N6)/L6)*100 -> 32.263514 | P6: ='Dia 0'!H5 -> 1560 | Q6: ='Dia 7'!H5 -> 685 | R6: ='Dia 14'!H5 -> 1340 | S6: =((P6-R6)/P6)*100 -> 14.102564 | T6: ='Dia 0'!M5 -> 1511.599 | U6: ='Dia 7'!M5 -> 618.751 | V6: ='Dia 14'!M5 -> 1311.883 | W6: =((T6-V6)/T6)*100 -> 13.212234
C7: 50 | D7: ='Dia 0'!D6 -> 9.24 | E7: ='Dia 7'!D6 -> 9.37 | F7: ='Dia 14'!D6 -> 8.8 | G7: =((D7-F7)/D7)*100 -> 4.7619048 | H7: ='Dia 0'!E6 -> 106 | I7: ='Dia 7'!E6 -> 107 | J7: ='Dia 14'!E6 -> 111 | K7: =((H7-J7)/H7)*100 -> -4.7169811 | L7: ='Dia 0'!F6 -> 10.78 | M7: ='Dia 7'!F6 -> 8.48 | N7: ='Dia 14'!F6 -> 7.86 | O7: =((L7-N7)/L7)*100 -> 27.087199 | P7: ='Dia 0'!H6 -> 2980 | Q7: ='Dia 7'!H6 -> 2780 | R7: ='Dia 14'!H6 -> 2800 | S7: =((P7-R7)/P7)*100 -> 6.0402685 | T7: ='Dia 0'!M6 -> 3015.343 | U7: ='Dia 7'!M6 -> 2369.203 | V7: ='Dia 14'!M6 -> 2510.179 | W7: =((T7-V7)/T7)*100 -> 16.753119
C8: 75 | D8: ='Dia 0'!D7 -> 9.26 | E8: ='Dia 7'!D7 -> 9.44 | F8: ='Dia 14'!D7 -> 8.88 | G8: =((D8-F8)/D8)*100 -> 4.1036717 | H8: ='Dia 0'!E7 -> 108 | I8: ='Dia 7'!E7 -> 143 | J8: ='Dia 14'!E7 -> 154 | K8: =((H8-J8)/H8)*100 -> -42.592593 | L8: ='Dia 0'!F7 -> 15.2 | M8: ='Dia 7'!F7 -> 13.36 | N8: ='Dia 14'!F7 -> 12.28 | O8: =((L8-N8)/L8)*100 -> 19.210526 | P8: ='Dia 0'!H7 -> 4240 | Q8: ='Dia 7'!H7 -> 1930 | R8: ='Dia 14'!H7 -> 3860 | S8: =((P8-R8)/P8)*100 -> 8.9622642 | T8: ='Dia 0'!M7 -> 3919.939 | U8: ='Dia 7'!M7 -> 1946.275 | V8: ='Dia 14'!M7 -> 4225.387 | W8: =((T8-V8)/T8)*100 -> -7.7921621
C9: 100 | D9: ='Dia 0'!D8 -> 9.27 | E9: ='Dia 7'!D8 -> 9.44 | F9: ='Dia 14'!D8 -> 8.89 | G9: =((D9-F9)/D9)*100 -> 4.0992449 | H9: ='Dia 0'!E8 -> 152 | I9: ='Dia 7'!E8 -> 156 | J9: ='Dia 14'!E8 -> 168 | K9: =((H9-J9)/H9)*100 -> -10.526316 | L9: ='Dia 0'!F8 -> 19.67 | M9: ='Dia 7'!F8 -> 17.64 | N9: ='Dia 14'!F8 -> 16.08 | O9: =((L9-N9)/L9)*100 -> 18.251144 | P9: ='Dia 0'!H8 -> 5780 | Q9: ='Dia 7'!H8 -> 2550 | R9: ='Dia 14'!H8 -> 5260 | S9: =((P9-R9)/P9)*100 -> 8.9965398 | T9: ='Dia 0'!M8 -> 5188.723 | U9: ='Dia 7'!M8 -> 2533.675 | V9: ='Dia 14'!M8 -> 5729.131 | W9: =((T9-V9)/T9)*100 -> -10.415048
P10: ='Dia 0'!H9 | T10: ='Dia 0'!M9
B11: A | C11: 0 | D11: ='Dia 0'!D10 -> 5.87 | E11: ='Dia 7'!D10 -> 8.47 | F11: ='Dia 14'!D10 -> 7.93 | G11: =((D11-F11)/D11)*100 -> -35.093697 | H11: ='Dia 0'!E10 -> 0.86 | I11: ='Dia 7'!E10 -> 0 | J11: ='Dia 14'!E10 -> 1.97 | K11: =((H11-J11)/H11)*100 -> -129.06977 | L11: ='Dia 0'!F10 -> 11.83 | M11: ='Dia 7'!F10 -> 20.2 | N11: ='Dia 14'!F10 -> 37.1 | O11: =((L11-N11)/L11)*100 -> -213.60947 | P11: ='Dia 0'!H10 -> 0 | Q11: ='Dia 7'!H10 -> 2 | R11: ='Dia 14'!H10 -> 0 | S11: =((P11-R11)/P11)*100 -> #DIV/0! | T11: ='Dia 0'!M10 -> 7.855 | U11: ='Dia 7'!M10 -> 14.9038 | V11: ='Dia 14'!M10 -> 20.7778 | W11: =((T11-V11)/T11)*100 -> -164.51687
C12: 25 | D12: ='Dia 0'!D11 -> 9.15 | E12: ='Dia 7'!D11 -> 9.26 | F12: ='Dia 14'!D11 -> 8.65 | G12: =((D12-F12)/D12)*100 -> 5.4644809 | H12: ='Dia 0'!E11 -> 56.2 | I12: ='Dia 7'!E11 -> 49.8 | J12: ='Dia 14'!E11 -> 53.5 | K12: =((H12-J12)/H12)*100 -> 4.8042705 | L12: ='Dia 0'!F11 -> 5.92 | M12: ='Dia 7'!F11 -> 4.37 | N12: ='Dia 14'!F11 -> 4.06 | O12: =((L12-N12)/L12)*100 -> 31.418919 | P12: ='Dia 0'!H11 -> 1560 | Q12: ='Dia 7'!H11 -> 495 | R12: ='Dia 14'!H11 -> 990 | S12: =((P12-R12)/P12)*100 -> 36.538462 | T12: ='Dia 0'!M11 -> 1511.599 | U12: ='Dia 7'!M11 -> 589.381 | V12: ='Dia 14'!M11 -> 1182.655 | W12: =((T12-V12)/T12)*100 -> 21.761327
C13: 50 | D13: ='Dia 0'!D12 -> 9.24 | E13: ='Dia 7'!D12 -> 9.38 | F13: ='Dia 14'!D12 -> 8.75 | G13: =((D13-F13)/D13)*100 -> 5.3030303 | H13: ='Dia 0'!E12 -> 106 | I13: ='Dia 7'!E12 -> 86.6 | J13: ='Dia 14'!E12 -> 100 | K13: =((H13-J13)/H13)*100 -> 5.6603774 | L13: ='Dia 0'!F12 -> 10.78 | M13: ='Dia 7'!F12 -> 8.41 | N13: ='Dia 14'!F12 -> 7.91 | O13: =((L13-N13)/L13)*100 -> 26.623377 | P13: ='Dia 0'!H12 -> 2980 | Q13: ='Dia 7'!H12 -> 2300 | R13: ='Dia 14'!H12 -> 2540 | S13: =((P13-R13)/P13)*100 -> 14.765101 | T13: ='Dia 0'!M12 -> 3015.343 | U13: ='Dia 7'!M12 -> 2275.219 | V13: ='Dia 14'!M12 -> 2322.211 | W13: =((T13-V13)/T13)*100 -> 22.986838
C14: 75 | D14: ='Dia 0'!D13 -> 9.26 | E14: ='Dia 7'!D13 -> 9.44 | F14: ='Dia 14'!D13 -> 8.73 | G14: =((D14-F14)/D14)*100 -> 5.7235421 | H14: ='Dia 0'!E13 -> 108 | I14: ='Dia 7'!E13 -> 136 | J14: ='Dia 14'!E13 -> 158 | K14: =((H14-J14)/H14)*100 -> -46.296296 | L14: ='Dia 0'!F13 -> 15.2 | M14: ='Dia 7'!F13 -> 13.03 | N14: ='Dia 14'!F13 -> 12.07 | O14: =((L14-N14)/L14)*100 -> 20.592105 | P14: ='Dia 0'!H13 -> 4240 | Q14: ='Dia 7'!H13 -> 1810 | R14: ='Dia 14'!H13 -> 4020 | S14: =((P14-R14)/P14)*100 -> 5.1886792 | T14: ='Dia 0'!M13 -> 3919.939 | U14: ='Dia 7'!M13 -> 1852.291 | V14: ='Dia 14'!M13 -> 3872.947 | W14: =((T14-V14)/T14)*100 -> 1.1987942
C15: 100 | D15: ='Dia 0'!D14 -> 9.27 | E15: ='Dia 7'!D14 -> 9.46 | F15: ='Dia 14'!D14 -> 8.9 | G15: =((D15-F15)/D15)*100 -> 3.99137 | H15: ='Dia 0'!E14 -> 152 | I15: ='Dia 7'!E14 -> 164 | J15: ='Dia 14'!E14 -> 183 | K15: =((H15-J15)/H15)*100 -> -20.394737 | L15: ='Dia 0'!F14 -> 19.67 | M15: ='Dia 7'!F14 -> 17.22 | N15: ='Dia 14'!F14 -> 15.84 | O15: =((L15-N15)/L15)*100 -> 19.471276 | P15: ='Dia 0'!H14 -> 5780 | Q15: ='Dia 7'!H14 -> 2540 | R15: ='Dia 14'!H14 -> 5040 | S15: =((P15-R15)/P15)*100 -> 12.802768 | T15: ='Dia 0'!M14 -> 5188.723 | U15: ='Dia 7'!M14 -> 2639.407 | V15: ='Dia 14'!M14 -> 4906.771 | W15: =((T15-V15)/T15)*100 -> 5.4339382
L16: ='Dia 0'!F15 | P16: ='Dia 0'!H15 | T16: ='Dia 0'!M15
B17: BI | C17: 0 | D17: ='Dia 0'!D16 -> 5.87 | E17: ='Dia 7'!D16 -> 8.85 | F17: ='Dia 14'!D16 -> 8.09 | G17: =((D17-F17)/D17)*100 -> -37.819421 | H17: ='Dia 0'!E16 -> 0.86 | I17: ='Dia 7'!E16 -> 0.61 | J17: ='Dia 14'!E16 -> 2.96 | K17: =((H17-J17)/H17)*100 -> -244.18605 | L17: ='Dia 0'!F16 -> 11.83 | M17: ='Dia 7'!F16 -> 37.4 | N17: ='Dia 14'!F16 -> 38.9 | O17: =((L17-N17)/L17)*100 -> -228.82502 | P17: ='Dia 0'!H16 -> 0 | Q17: ='Dia 7'!H16 -> 51 | R17: ='Dia 14'!H16 -> 40 | S17: =((P17-R17)/P17)*100 -> #DIV/0! | T17: ='Dia 0'!M16 -> 7.855 | U17: ='Dia 7'!M16 -> 85.3918 | V17: ='Dia 14'!M16 -> 50.1478 | W17: =((T17-V17)/T17)*100 -> -538.41884
C18: 25 | D18: ='Dia 0'!D17 -> 8.33 | E18: ='Dia 7'!D17 -> 9.22 | F18: ='Dia 14'!D17 -> 8.66 | G18: =((D18-F18)/D18)*100 -> -3.9615846 | H18: ='Dia 0'!E17 -> 26.2 | I18: ='Dia 7'!E17 -> 45.1 | J18: ='Dia 14'!E17 -> 30.4 | K18: =((H18-J18)/H18)*100 -> -16.030534 | L18: ='Dia 0'!F17 -> 7.48 | M18: ='Dia 7'!F17 -> 4.95 | N18: ='Dia 14'!F17 -> 4.44 | O18: =((L18-N18)/L18)*100 -> 40.641711 | P18: ='Dia 0'!H17 -> 1315 | Q18: ='Dia 7'!H17 -> 645 | R18: ='Dia 14'!H17 -> 1330 | S18: =((P18-R18)/P18)*100 -> -1.1406844 | T18: ='Dia 0'!M17 -> 1611.457 | U18: ='Dia 7'!M17 -> 659.869 | V18: ='Dia 14'!M17 -> 1123.915 | W18: =((T18-V18)/T18)*100 -> 30.254732
C19: 50 | D19: ='Dia 0'!D18 -> 8.31 | E19: ='Dia 7'!D18 -> 9.34 | F19: ='Dia 14'!D18 -> 8.72 | G19: =((D19-F19)/D19)*100 -> -4.9338147 | H19: ='Dia 0'!E18 -> 41.8 | I19: ='Dia 7'!E18 -> 87.7 | J19: ='Dia 14'!E18 -> 55.2 | K19: =((H19-J19)/H19)*100 -> -32.057416 | L19: ='Dia 0'!F18 -> 13.65 | M19: ='Dia 7'!F18 -> 9.85 | N19: ='Dia 14'!F18 -> 8.74 | O19: =((L19-N19)/L19)*100 -> 35.970696 | P19: ='Dia 0'!H18 -> 2380 | Q19: ='Dia 7'!H18 -> 2910 | R19: ='Dia 14'!H18 -> 2740 | S19: =((P19-R19)/P19)*100 -> -15.12605 | T19: ='Dia 0'!M18 -> 2980.099 | U19: ='Dia 7'!M18 -> 2580.667 | V19: ='Dia 14'!M18 -> 2357.455 | W19: =((T19-V19)/T19)*100 -> 20.8934
C20: 75 | D20: ='Dia 0'!D19 -> 8.34 | E20: ='Dia 7'!D19 -> 9.3 | F20: ='Dia 14'!D19 -> 8.75 | G20: =((D20-F20)/D20)*100 -> -4.9160671 | H20: ='Dia 0'!E19 -> 62.7 | I20: ='Dia 7'!E19 -> 89.3 | J20: ='Dia 14'!E19 -> 88.3 | K20: =((H20-J20)/H20)*100 -> -40.829346 | L20: ='Dia 0'!F19 -> 19.62 | M20: ='Dia 7'!F19 -> 14.8 | N20: ='Dia 14'!F19 -> 13.29 | O20: =((L20-N20)/L20)*100 -> 32.262997 | P20: ='Dia 0'!H19 -> 3660 | Q20: ='Dia 7'!H19 -> 1930 | R20: ='Dia 14'!H19 -> 4120 | S20: =((P20-R20)/P20)*100 -> -12.568306 | T20: ='Dia 0'!M19 -> 4554.331 | U20: ='Dia 7'!M19 -> 1887.535 | V20: ='Dia 14'!M19 -> 3919.939 | W20: =((T20-V20)/T20)*100 -> 13.929422
C21: 100 | D21: ='Dia 0'!D20 -> 8.21 | E21: ='Dia 7'!D20 -> 9.33 | F21: ='Dia 14'!D20 -> 8.78 | G21: =((D21-F21)/D21)*100 -> -6.9427527 | H21: ='Dia 0'!E20 -> 77.8 | I21: ='Dia 7'!E20 -> 104 | J21: ='Dia 14'!E20 -> 108 | K21: =((H21-J21)/H21)*100 -> -38.817481 | L21: ='Dia 0'!F20 -> 24.94 | M21: ='Dia 7'!F20 -> 18.21 | N21: ='Dia 14'!F20 -> 16.72 | O21: =((L21-N21)/L21)*100 -> 32.959102 | P21: ='Dia 0'!H20 -> 5160 | Q21: ='Dia 7'!H20 -> 4840 | R21: ='Dia 14'!H20 -> 5380 | S21: =((P21-R21)/P21)*100 -> -4.2635659 | T21: ='Dia 0'!M20 -> 6199.051 | U21: ='Dia 7'!M20 -> 2427.943 | V21: ='Dia 14'!M20 -> 5165.227 | W21: =((T21-V21)/T21)*100 -> 16.677133
P22: ='Dia 0'!H21 | T22: ='Dia 0'!M21
B23: B | C23: 0 | D23: ='Dia 0'!D22 -> 5.87 | E23: ='Dia 7'!D22 -> 8.47 | F23: ='Dia 14'!D22 -> 8.04 | G23: =((D23-F23)/D23)*100 -> -36.967632 | H23: ='Dia 0'!E22 -> 0.86 | I23: ='Dia 7'!E22 -> 0 | J23: ='Dia 14'!E22 -> 1.62 | K23: =((H23-J23)/H23)*100 -> -88.372093 | L23: ='Dia 0'!F22 -> 11.83 | M23: ='Dia 7'!F22 -> 20.2 | N23: ='Dia 14'!F22 -> 22.18 | O23: =((L23-N23)/L23)*100 -> -87.489434 | P23: ='Dia 0'!H22 -> 0 | Q23: ='Dia 7'!H22 -> 2 | R23: ='Dia 14'!H22 -> 1 | S23: =((P23-R23)/P23)*100 -> #DIV/0! | T23: ='Dia 0'!M22 -> 7.855 | U23: ='Dia 7'!M22 -> 14.9038 | V23: ='Dia 14'!M22 -> 25.477 | W23: =((T23-V23)/T23)*100 -> -224.34118
C24: 25 | D24: ='Dia 0'!D23 -> 8.33 | E24: ='Dia 7'!D23 -> 9.29 | F24: ='Dia 14'!D23 -> 8.72 | G24: =((D24-F24)/D24)*100 -> -4.6818727 | H24: ='Dia 0'!E23 -> 26.2 | I24: ='Dia 7'!E23 -> 33.3 | J24: ='Dia 14'!E23 -> 30.8 | K24: =((H24-J24)/H24)*100 -> -17.557252 | L24: ='Dia 0'!F23 -> 7.48 | M24: ='Dia 7'!F23 -> 5.06 | N24: ='Dia 14'!F23 -> 4.63 | O24: =((L24-N24)/L24)*100 -> 38.101604 | P24: ='Dia 0'!H23 -> 1315 | Q24: ='Dia 7'!H23 -> 595 | R24: ='Dia 14'!H23 -> 1330 | S24: =((P24-R24)/P24)*100 -> -1.1406844 | T24: ='Dia 0'!M23 -> 1611.457 | U24: ='Dia 7'!M23 -> 659.869 | V24: ='Dia 14'!M23 -> 1370.623 | W24: =((T24-V24)/T24)*100 -> 14.945109
C25: 50 | D25: ='Dia 0'!D24 -> 8.31 | E25: ='Dia 7'!D24 -> 9.34 | F25: ='Dia 14'!D24 -> 8.79 | G25: =((D25-F25)/D25)*100 -> -5.7761733 | H25: ='Dia 0'!E24 -> 41.8 | I25: ='Dia 7'!E24 -> 60.3 | J25: ='Dia 14'!E24 -> 63.5 | K25: =((H25-J25)/H25)*100 -> -51.913876 | L25: ='Dia 0'!F24 -> 13.65 | M25: ='Dia 7'!F24 -> 9.91 | N25: ='Dia 14'!F24 -> 8.91 | O25: =((L25-N25)/L25)*100 -> 34.725275 | P25: ='Dia 0'!H24 -> 2380 | Q25: ='Dia 7'!H24 -> 2590 | R25: ='Dia 14'!H24 -> 2740 | S25: =((P25-R25)/P25)*100 -> -15.12605 | T25: ='Dia 0'!M24 -> 2980.099 | U25: ='Dia 7'!M24 -> 2580.667 | V25: ='Dia 14'!M24 -> 2580.667 | W25: =((T25-V25)/T25)*100 -> 13.403313
C26: 75 | D26: ='Dia 0'!D25 -> 8.34 | E26: ='Dia 7'!D25 -> 9.36 | F26: ='Dia 14'!D25 -> 8.8 | G26: =((D26-F26)/D26)*100 -> -5.5155875 | H26: ='Dia 0'!E25 -> 62.7 | I26: ='Dia 7'!E25 -> 79.3 | J26: ='Dia 14'!E25 -> 82.7 | K26: =((H26-J26)/H26)*100 -> -31.897927 | L26: ='Dia 0'!F25 -> 19.62 | M26: ='Dia 7'!F25 -> 14.52 | N26: ='Dia 14'!F25 -> 13.3 | O26: =((L26-N26)/L26)*100 -> 32.212029 | P26: ='Dia 0'!H25 -> 3660 | Q26: ='Dia 7'!H25 -> 1890 | R26: ='Dia 14'!H25 -> 4120 | S26: =((P26-R26)/P26)*100 -> -12.568306 | T26: ='Dia 0'!M25 -> 4554.331 | U26: ='Dia 7'!M25 -> 1887.535 | V26: ='Dia 14'!M25 -> 5212.219 | W26: =((T26-V26)/T26)*100 -> -14.445327
C27: 100 | D27: ='Dia 0'!D26 -> 8.21 | E27: ='Dia 7'!D26 -> 9.3 | F27: ='Dia 14'!D26 -> 8.76 | G27: =((D27-F27)/D27)*100 -> -6.6991474 | H27: ='Dia 0'!E26 -> 77.8 | I27: ='Dia 7'!E26 -> 95.5 | J27: ='Dia 14'!E26 -> 106 | K27: =((H27-J27)/H27)*100 -> -36.246787 | L27: ='Dia 0'!F26 -> 24.94 | M27: ='Dia 7'!F26 -> 17.74 | N27: ='Dia 14'!F26 -> 16.7 | O27: =((L27-N27)/L27)*100 -> 33.039294 | P27: ='Dia 0'!H26 -> 5160 | Q27: ='Dia 7'!H26 -> 2460 | R27: ='Dia 14'!H26 -> 5380 | S27: =((P27-R27)/P27)*100 -> -4.2635659 | T27: ='Dia 0'!M26 -> 6199.051 | U27: ='Dia 7'!M26 -> 2427.943 | V27: ='Dia 14'!M26 -> 5329.699 | W27: =((T27-V27)/T27)*100 -> 14.023953

Sheet Gráficos
B2: AI | C2: Dia 0 | D2: Dia 7 | E2: Dia 14 | I2: A | J2: Dia 0 | K2: Dia 7 | L2: Dia 14 | Q2: I | R2: Dia 0 | S2: Dia 7 | T2: Dia 14 | Y2: Concentrações | Z2: Dia 0 | AA2: Dia 7 | AB2: Dia 14
C3: pH | J3: pH | R3: pH | Z3: pH
B4: 0 | C4: =PROCESSAMENTO!D5 -> 5.87 | D4: =PROCESSAMENTO!E5 -> 8.85 | E4: =PROCESSAMENTO!F5 -> 5.83 | I4: 0 | J4: =PROCESSAMENTO!D11 -> 5.87 | K4: =PROCESSAMENTO!E11 -> 8.47 | L4: =PROCESSAMENTO!F11 -> 7.93 | Q4: 0 | R4: =PROCESSAMENTO!D17 -> 5.87 | S4: =PROCESSAMENTO!E17 -> 8.85 | T4: =PROCESSAMENTO!F17 -> 8.09 | Y4: 0 | Z4: =PROCESSAMENTO!D23 -> 5.87 | AA4: =PROCESSAMENTO!E23 -> 8.47 | AB4: =PROCESSAMENTO!F23 -> 8.04
B5: 25 | C5: =PROCESSAMENTO!D6 -> 9.15 | D5: =PROCESSAMENTO!E6 -> 9.25 | E5: =PROCESSAMENTO!F6 -> 8.65 | I5: 25 | J5: =PROCESSAMENTO!D12 -> 9.15 | K5: =PROCESSAMENTO!E12 -> 9.26 | L5: =PROCESSAMENTO!F12 -> 8.65 | Q5: 25 | R5: =PROCESSAMENTO!D18 -> 8.33 | S5: =PROCESSAMENTO!E18 -> 9.22 | T5: =PROCESSAMENTO!F18 -> 8.66 | Y5: 25 | Z5: =PROCESSAMENTO!D24 -> 8.33 | AA5: =PROCESSAMENTO!E24 -> 9.29 | AB5: =PROCESSAMENTO!F24 -> 8.72
B6: 50 | C6: =PROCESSAMENTO!D7 -> 9.24 | D6: =PROCESSAMENTO!E7 -> 9.37 | E6: =PROCESSAMENTO!F7 -> 8.8 | I6: 50 | J6: =PROCESSAMENTO!D13 -> 9.24 | K6: =PROCESSAMENTO!E13 -> 9.38 | L6: =PROCESSAMENTO!F13 -> 8.75 | Q6: 50 | R6: =PROCESSAMENTO!D19 -> 8.31 | S6: =PROCESSAMENTO!E19 -> 9.34 | T6: =PROCESSAMENTO!F19 -> 8.72 | Y6: 50 | Z6: =PROCESSAMENTO!D25 -> 8.31 | AA6: =PROCESSAMENTO!E25 -> 9.34 | AB6: =PROCESSAMENTO!F25 -> 8.79
B7: 75 | C7: =PROCESSAMENTO!D8 -> 9.26 | D7: =PROCESSAMENTO!E8 -> 9.44 | E7: =PROCESSAMENTO!F8 -> 8.88 | I7: 75 | J7: =PROCESSAMENTO!D14 -> 9.26 | K7: =PROCESSAMENTO!E14 -> 9.44 | L7: =PROCESSAMENTO!F14 -> 8.73 | Q7: 75 | R7: =PROCESSAMENTO!D20 -> 8.34 | S7: =PROCESSAMENTO!E20 -> 9.3 | T7: =PROCESSAMENTO!F20 -> 8.75 | Y7: 75 | Z7: =PROCESSAMENTO!D26 -> 8.34 | AA7: =PROCESSAMENTO!E26 -> 9.36 | AB7: =PROCESSAMENTO!F26 -> 8.8
B8: 100 | C8: =PROCESSAMENTO!D9 -> 9.27 | D8: =PROCESSAMENTO!E9 -> 9.44 | E8: =PROCESSAMENTO!F9 -> 8.89 | I8: 100 | J8: =PROCESSAMENTO!D15 -> 9.27 | K8: =PROCESSAMENTO!E15 -> 9.46 | L8: =PROCESSAMENTO!F15 -> 8.9 | Q8: 100 | R8: =PROCESSAMENTO!D21 -> 8.21 | S8: =PROCESSAMENTO!E21 -> 9.33 | T8: =PROCESSAMENTO!F21 -> 8.78 | Y8: 100 | Z8: =PROCESSAMENTO!D27 -> 8.21 | AA8: =PROCESSAMENTO!E27 -> 9.3 | AB8: =PROCESSAMENTO!F27 -> 8.76
B10: AI | C10: Dia 0 | D10: Dia 7 | E10: Dia 14 | I10: A | J10: Dia 0 | K10: Dia 7 | L10: Dia 14 | Q10: I | R10: Dia 0 | S10: Dia 7 | T10: Dia 14 | Y10: Concentrações | Z10: Dia 0 | AA10: Dia 7 | AB10: Dia 14
C11: TURBIDEZ (NTU) | J11: TURBIDEZ (NTU) | R11: TURBIDEZ (NTU) | Z11: TURBIDEZ (NTU)
B12: 0 | C12: =PROCESSAMENTO!H5 -> 0.86 | D12: =PROCESSAMENTO!I5 -> 0.061 | E12: =PROCESSAMENTO!J5 -> 2.07 | I12: 0 | J12: =PROCESSAMENTO!H11 -> 0.86 | K12: =PROCESSAMENTO!I11 -> 0 | L12: =PROCESSAMENTO!J11 -> 1.97 | Q12: 0 | R12: =PROCESSAMENTO!H17 -> 0.86 | S12: =PROCESSAMENTO!I17 -> 0.61 | T12: =PROCESSAMENTO!J17 -> 2.96 | Y12: 0 | Z12: =PROCESSAMENTO!H23 -> 0.86 | AA12: =PROCESSAMENTO!I23 -> 0 | AB12: =PROCESSAMENTO!J23 -> 1.62
B13: 25 | C13: =PROCESSAMENTO!H6 -> 56.2 | D13: =PROCESSAMENTO!I6 -> 65.5 | E13: =PROCESSAMENTO!J6 -> 66.7 | I13: 25 | J13: =PROCESSAMENTO!H12 -> 56.2 | K13: =PROCESSAMENTO!I12 -> 49.8 | L13: =PROCESSAMENTO!J12 -> 53.5 | Q13: 25 | R13: =PROCESSAMENTO!H18 -> 26.2 | S13: =PROCESSAMENTO!I18 -> 45.1 | T13: =PROCESSAMENTO!J18 -> 30.4 | Y13: 25 | Z13: =PROCESSAMENTO!H24 -> 26.2 | AA13: =PROCESSAMENTO!I24 -> 33.3 | AB13: =PROCESSAMENTO!J24 -> 30.8
B14: 50 | C14: =PROCESSAMENTO!H7 -> 106 | D14: =PROCESSAMENTO!I7 -> 107 | E14: =PROCESSAMENTO!J7 -> 111 | I14: 50 | J14: =PROCESSAMENTO!H13 -> 106 | K14: =PROCESSAMENTO!I13 -> 86.6 | L14: =PROCESSAMENTO!J13 -> 100 | Q14: 50 | R14: =PROCESSAMENTO!H19 -> 41.8 | S14: =PROCESSAMENTO!I19 -> 87.7 | T14: =PROCESSAMENTO!J19 -> 55.2 | Y14: 50 | Z14: =PROCESSAMENTO!H25 -> 41.8 | AA14: =PROCESSAMENTO!I25 -> 60.3 | AB14: =PROCESSAMENTO!J25 -> 63.5
B15: 75 | C15: =PROCESSAMENTO!H8 -> 108 | D15: =PROCESSAMENTO!I8 -> 143 | E15: =PROCESSAMENTO!J8 -> 154 | I15: 75 | J15: =PROCESSAMENTO!H14 -> 108 | K15: =PROCESSAMENTO!I14 -> 136 | L15: =PROCESSAMENTO!J14 -> 158 | Q15: 75 | R15: =PROCESSAMENTO!H20 -> 62.7 | S15: =PROCESSAMENTO!I20 -> 89.3 | T15: =PROCESSAMENTO!J20 -> 88.3 | Y15: 75 | Z15: =PROCESSAMENTO!H26 -> 62.7 | AA15: =PROCESSAMENTO!I26 -> 79.3 | AB15: =PROCESSAMENTO!J26 -> 82.7
B16: 100 | C16: =PROCESSAMENTO!H9 -> 152 | D16: =PROCESSAMENTO!I9 -> 156 | E16: =PROCESSAMENTO!J9 -> 168 | I16: 100 | J16: =PROCESSAMENTO!H15 -> 152 | K16: =PROCESSAMENTO!I15 -> 164 | L16: =PROCESSAMENTO!J15 -> 183 | Q16: 100 | R16: =PROCESSAMENTO!H21 -> 77.8 | S16: =PROCESSAMENTO!I21 -> 104 | T16: =PROCESSAMENTO!J21 -> 108 | Y16: 100 | Z16: =PROCESSAMENTO!H27 -> 77.8 | AA16: =PROCESSAMENTO!I27 -> 95.5 | AB16: =PROCESSAMENTO!J27 -> 106
B18: AI | C18: Dia 0 | D18: Dia 7 | E18: Dia 14 | I18: A | J18: Dia 0 | K18: Dia 7 | L18: Dia 14 | Q18: I | R18: Dia 0 | S18: Dia 7 | T18: Dia 14 | Y18: Concentrações | Z18: Dia 0 | AA18: Dia 7 | AB18: Dia 14
C19: CONDUTIVIDADE mS/cm | J19: CONDUTIVIDADE mS/cm | R19: CONDUTIVIDADE mS/cm | Z19: CONDUTIVIDADE mS/cm
B20: 0 | C20: =PROCESSAMENTO!L5 -> 11.83 | D20: =PROCESSAMENTO!M5 -> 37.4 | E20: =PROCESSAMENTO!N5 -> 31.7 | I20: 0 | J20: =PROCESSAMENTO!L11 -> 11.83 | K20: =PROCESSAMENTO!M11 -> 20.2 | L20: =PROCESSAMENTO!N11 -> 37.1 | Q20: 0 | R20: =PROCESSAMENTO!L17 -> 11.83 | S20: =PROCESSAMENTO!M17 -> 37.4 | T20: =PROCESSAMENTO!N17 -> 38.9 | Y20: 0 | Z20: =PROCESSAMENTO!L23 -> 11.83 | AA20: =PROCESSAMENTO!M23 -> 20.2 | AB20: =PROCESSAMENTO!N23 -> 22.18
B21: 25 | C21: =PROCESSAMENTO!L6 -> 5.92 | D21: =PROCESSAMENTO!M6 -> 4.5 | E21: =PROCESSAMENTO!N6 -> 4.01 | I21: 25 | J21: =PROCESSAMENTO!L12 -> 5.92 | K21: =PROCESSAMENTO!M12 -> 4.37 | L21: =PROCESSAMENTO!N12 -> 4.06 | Q21: 25 | R21: =PROCESSAMENTO!L18 -> 7.48 | S21: =PROCESSAMENTO!M18 -> 4.95 | T21: =PROCESSAMENTO!N18 -> 4.44 | Y21: 25 | Z21: =PROCESSAMENTO!L24 -> 7.48 | AA21: =PROCESSAMENTO!M24 -> 5.06 | AB21: =PROCESSAMENTO!N24 -> 4.63
B22: 50 | C22: =PROCESSAMENTO!L7 -> 10.78 | D22: =PROCESSAMENTO!M7 -> 8.48 | E22: =PROCESSAMENTO!N7 -> 7.86 | I22: 50 | J22: =PROCESSAMENTO!L13 -> 10.78 | K22: =PROCESSAMENTO!M13 -> 8.41 | L22: =PROCESSAMENTO!N13 -> 7.91 | Q22: 50 | R22: =PROCESSAMENTO!L19 -> 13.65 | S22: =PROCESSAMENTO!M19 -> 9.85 | T22: =PROCESSAMENTO!N19 -> 8.74 | Y22: 50 | Z22: =PROCESSAMENTO!L25 -> 13.65 | AA22: =PROCESSAMENTO!M25 -> 9.91 | AB22: =PROCESSAMENTO!N25 -> 8.91
B23: 75 | C23: =PROCESSAMENTO!L8 -> 15.2 | D23: =PROCESSAMENTO!M8 -> 13.36 | E23: =PROCESSAMENTO!N8 -> 12.28 | I23: 75 | J23: =PROCESSAMENTO!L14 -> 15.2 | K23: =PROCESSAMENTO!M14 -> 13.03 | L23: =PROCESSAMENTO!N14 -> 12.07 | Q23: 75 | R23: =PROCESSAMENTO!L20 -> 19.62 | S23: =PROCESSAMENTO!M20 -> 14.8 | T23: =PROCESSAMENTO!N20 -> 13.29 | Y23: 75 | Z23: =PROCESSAMENTO!L26 -> 19.62 | AA23: =PROCESSAMENTO!M26 -> 14.52 | AB23: =PROCESSAMENTO!N26 -> 13.3
B24: 100 | C24: =PROCESSAMENTO!L9 -> 19.67 | D24: =PROCESSAMENTO!M9 -> 17.64 | E24: =PROCESSAMENTO!N9 -> 16.08 | I24: 100 | J24: =PROCESSAMENTO!L15 -> 19.67 | K24: =PROCESSAMENTO!M15 -> 17.22 | L24: =PROCESSAMENTO!N15 -> 15.84 | Q24: 100 | R24: =PROCESSAMENTO!L21 -> 24.94 | S24: =PROCESSAMENTO!M21 -> 18.21 | T24: =PROCESSAMENTO!N21 -> 16.72 | Y24: 100 | Z24: =PROCESSAMENTO!L27 -> 24.94 | AA24: =PROCESSAMENTO!M27 -> 17.74 | AB24: =PROCESSAMENTO!N27 -> 16.7
B26: AI | C26: Dia 0 | D26: Dia 7 | E26: Dia 14 | I26: A | J26: Dia 0 | K26: Dia 7 | L26: Dia 14 | Q26: I | R26: Dia 0 | S26: Dia 7 | T26: Dia 14 | Y26: Concentrações | Z26: Dia 0 | AA26: Dia 7 | AB26: Dia 14
C27: COR | J27: COR | R27: COR | Z27: COR
B28: 0 | C28: =PROCESSAMENTO!P5 -> 0 | D28: =PROCESSAMENTO!Q5 -> 51 | E28: =PROCESSAMENTO!R5 -> 39 | I28: 0 | J28: =PROCESSAMENTO!P11 -> 0 | K28: =PROCESSAMENTO!Q11 -> 2 | L28: =PROCESSAMENTO!R11 -> 0 | Q28: 0 | R28: =PROCESSAMENTO!P17 -> 0 | S28: =PROCESSAMENTO!Q17 -> 51 | T28: =PROCESSAMENTO!R17 -> 40 | Y28: 0 | Z28: =PROCESSAMENTO!P23 -> 0 | AA28: =PROCESSAMENTO!Q23 -> 2 | AB28: =PROCESSAMENTO!R23 -> 1
B29: 25 | C29: =PROCESSAMENTO!P6 -> 1560 | D29: =PROCESSAMENTO!Q6 -> 685 | E29: =PROCESSAMENTO!R6 -> 1340 | I29: 25 | J29: =PROCESSAMENTO!P12 -> 1560 | K29: =PROCESSAMENTO!Q12 -> 495 | L29: =PROCESSAMENTO!R12 -> 990 | Q29: 25 | R29: =PROCESSAMENTO!P18 -> 1315 | S29: =PROCESSAMENTO!Q18 -> 645 | T29: =PROCESSAMENTO!R18 -> 1330 | Y29: 25 | Z29: =PROCESSAMENTO!P24 -> 1315 | AA29: =PROCESSAMENTO!Q24 -> 595 | AB29: =PROCESSAMENTO!R24 -> 1330
B30: 50 | C30: =PROCESSAMENTO!P7 -> 2980 | D30: =PROCESSAMENTO!Q7 -> 2780 | E30: =PROCESSAMENTO!R7 -> 2800 | I30: 50 | J30: =PROCESSAMENTO!P13 -> 2980 | K30: =PROCESSAMENTO!Q13 -> 2300 | L30: =PROCESSAMENTO!R13 -> 2540 | Q30: 50 | R30: =PROCESSAMENTO!P19 -> 2380 | S30: =PROCESSAMENTO!Q19 -> 2910 | T30: =PROCESSAMENTO!R19 -> 2740 | Y30: 50 | Z30: =PROCESSAMENTO!P25 -> 2380 | AA30: =PROCESSAMENTO!Q25 -> 2590 | AB30: =PROCESSAMENTO!R25 -> 2740
B31: 75 | C31: =PROCESSAMENTO!P8 -> 4240 | D31: =PROCESSAMENTO!Q8 -> 1930 | E31: =PROCESSAMENTO!R8 -> 3860 | I31: 75 | J31: =PROCESSAMENTO!P14 -> 4240 | K31: =PROCESSAMENTO!Q14 -> 1810 | L31: =PROCESSAMENTO!R14 -> 4020 | Q31: 75 | R31: =PROCESSAMENTO!P20 -> 3660 | S31: =PROCESSAMENTO!Q20 -> 1930 | T31: =PROCESSAMENTO!R20 -> 4120 | Y31: 75 | Z31: =PROCESSAMENTO!P26 -> 3660 | AA31: =PROCESSAMENTO!Q26 -> 1890 | AB31: =PROCESSAMENTO!R26 -> 4120
B32: 100 | C32: =PROCESSAMENTO!P9 -> 5780 | D32: =PROCESSAMENTO!Q9 -> 2550 | E32: =PROCESSAMENTO!R9 -> 5260 | I32: 100 | J32: =PROCESSAMENTO!P15 -> 5780 | K32: =PROCESSAMENTO!Q15 -> 2540 | L32: =PROCESSAMENTO!R15 -> 5040 | Q32: 100 | R32: =PROCESSAMENTO!P21 -> 5160 | S32: =PROCESSAMENTO!Q21 -> 4840 | T32: =PROCESSAMENTO!R21 -> 5380 | Y32: 100 | Z32: =PROCESSAMENTO!P27 -> 5160 | AA32: =PROCESSAMENTO!Q27 -> 2460 | AB32: =PROCESSAMENTO!R27 -> 5380
B34: AI | C34: Dia 0 | D34: Dia 7 | E34: Dia 14 | I34: A | J34: Dia 0 | K34: Dia 7 | L34: Dia 14 | Q34: I | R34: Dia 0 | S34: Dia 7 | T34: Dia 14 | Y34: Concentrações | Z34: Dia 0 | AA34: Dia 7 | AB34: Dia 14
C35: DQO | J35: DQO | R35: DQO | Z35: DQO
B36: 0 | C36: =PROCESSAMENTO!T5 -> 7.855 | D36: =PROCESSAMENTO!U5 -> 85.3918 | E36: =PROCESSAMENTO!V5 -> 50.1478 | I36: 0 | J36: =PROCESSAMENTO!T11 -> 7.855 | K36: =PROCESSAMENTO!U11 -> 14.9038 | L36: =PROCESSAMENTO!V11 -> 20.7778 | Q36: 0 | R36: =PROCESSAMENTO!T17 -> 7.855 | S36: =PROCESSAMENTO!U17 -> 85.3918 | T36: =PROCESSAMENTO!V17 -> 50.1478 | Y36: 0 | Z36: =PROCESSAMENTO!T23 -> 7.855 | AA36: =PROCESSAMENTO!U23 -> 14.9038 | AB36: =PROCESSAMENTO!V23 -> 25.477
B37: 25 | C37: =PROCESSAMENTO!T6 -> 1511.599 | D37: =PROCESSAMENTO!U6 -> 618.751 | E37: =PROCESSAMENTO!V6 -> 1311.883 | I37: 25 | J37: =PROCESSAMENTO!T12 -> 1511.599 | K37: =PROCESSAMENTO!U12 -> 589.381 | L37: =PROCESSAMENTO!V12 -> 1182.655 | Q37: 25 | R37: =PROCESSAMENTO!T18 -> 1611.457 | S37: =PROCESSAMENTO!U18 -> 659.869 | T37: =PROCESSAMENTO!V18 -> 1123.915 | Y37: 25 | Z37: =PROCESSAMENTO!T24 -> 1611.457 | AA37: =PROCESSAMENTO!U24 -> 659.869 | AB37: =PROCESSAMENTO!V24 -> 1370.623
B38: 50 | C38: =PROCESSAMENTO!T7 -> 3015.343 | D38: =PROCESSAMENTO!U7 -> 2369.203 | E38: =PROCESSAMENTO!V7 -> 2510.179 | I38: 50 | J38: =PROCESSAMENTO!T13 -> 3015.343 | K38: =PROCESSAMENTO!U13 -> 2275.219 | L38: =PROCESSAMENTO!V13 -> 2322.211 | Q38: 50 | R38: =PROCESSAMENTO!T19 -> 2980.099 | S38: =PROCESSAMENTO!U19 -> 2580.667 | T38: =PROCESSAMENTO!V19 -> 2357.455 | Y38: 50 | Z38: =PROCESSAMENTO!T25 -> 2980.099 | AA38: =PROCESSAMENTO!U25 -> 2580.667 | AB38: =PROCESSAMENTO!V25 -> 2580.667
B39: 75 | C39: =PROCESSAMENTO!T8 -> 3919.939 | D39: =PROCESSAMENTO!U8 -> 1946.275 | E39: =PROCESSAMENTO!V8 -> 4225.387 | I39: 75 | J39: =PROCESSAMENTO!T14 -> 3919.939 | K39: =PROCESSAMENTO!U14 -> 1852.291 | L39: =PROCESSAMENTO!V14 -> 3872.947 | Q39: 75 | R39: =PROCESSAMENTO!T20 -> 4554.331 | S39: =PROCESSAMENTO!U20 -> 1887.535 | T39: =PROCESSAMENTO!V20 -> 3919.939 | Y39: 75 | Z39: =PROCESSAMENTO!T26 -> 4554.331 | AA39: =PROCESSAMENTO!U26 -> 1887.535 | AB39: =PROCESSAMENTO!V26 -> 5212.219
B40: 100 | C40: =PROCESSAMENTO!T9 -> 5188.723 | D40: =PROCESSAMENTO!U9 -> 2533.675 | E40: =PROCESSAMENTO!V9 -> 5729.131 | I40: 100 | J40: =PROCESSAMENTO!T15 -> 5188.723 | K40: =PROCESSAMENTO!U15 -> 2639.407 | L40: =PROCESSAMENTO!V15 -> 4906.771 | Q40: 100 | R40: =PROCESSAMENTO!T21 -> 6199.051 | S40: =PROCESSAMENTO!U21 -> 2427.943 | T40: =PROCESSAMENTO!V21 -> 5165.227 | Y40: 100 | Z40: =PROCESSAMENTO!T27 -> 6199.051 | AA40: =PROCESSAMENTO!U27 -> 2427.943 | AB40: =PROCESSAMENTO!V27 -> 5329.699
B42: DEGRADAÇÃO DE DQO (%)
B44: (%) | C44: AI | D44: A | E44: I | F44: B
B45: 0 | C45: =PROCESSAMENTO!W5 -> -538.41884 | D45: =PROCESSAMENTO!W11 -> -164.51687 | E45: =PROCESSAMENTO!W17 -> -538.41884 | F45: =PROCESSAMENTO!W23 -> -224.34118
B46: 25 | C46: =PROCESSAMENTO!W6 -> 13.212234 | D46: =PROCESSAMENTO!W12 -> 21.761327 | E46: =PROCESSAMENTO!W18 -> 30.254732 | F46: =PROCESSAMENTO!W24 -> 14.945109
B47: 50 | C47: =PROCESSAMENTO!W7 -> 16.753119 | D47: =PROCESSAMENTO!W13 -> 22.986838 | E47: =PROCESSAMENTO!W19 -> 20.8934 | F47: =PROCESSAMENTO!W25 -> 13.403313
...
