Workbook

Sheet Dia 0
B2: Tabela de Crescimento Radicular
B3: Tamanho (cm)
B4: Duplicata | C4: Controles | G4: AI | L4: A | Q4: BI | V4: B
C5: CN - M | D5: CN - T | E5: CN - D | F5: CP | G5: 0% | H5: 25% | I5: 50% | J5: 0.75 | K5: 1 | L5: 0% | M5: 25% | N5: 50% | O5: 0.75 | P5: 1 | Q5: 0% | R5: 25% | S5: 50% | T5: 0.75 | U5: 1 | V5: 0% | W5: 25% | X5: 50% | Y5: 0.75 | Z5: 1
B7: 1 | C7: 2.447 | D7: 1.697 | E7: 2.713 | F7: 0.212 | G7: 0.174 | H7: 0.101 | I7: 0.624 | J7: 0.246 | K7: 0.295 | L7: 0.695 | M7: 0.388 | N7: 0.232 | O7: 0.156 | Q7: 1.675 | R7: 0.431 | S7: 0.686 | V7: 1.049 | W7: 0.338 | X7: 0.17 | Y7: 0.073
C8: 2.597 | D8: 2.783 | E8: 2.496 | F8: 0.319 | G8: 1.704 | H8: 1.875 | I8: 1.308 | J8: 0.594 | L8: 0.784 | M8: 0.695 | N8: 0.25 | O8: 0.118 | Q8: 2.836 | R8: 1.012 | S8: 0.983 | V8: 0.9 | W8: 0.151 | X8: 0.409
C9: 2.844 | D9: 3.373 | E9: 3.394 | F9: 0.095 | G9: 0.307 | H9: 2.268 | I9: 1.944 | J9: 0.115 | L9: 0.486 | M9: 0.734 | N9: 0.114 | O9: 0.358 | Q9: 1.898 | R9: 1.836 | S9: 0.077 | V9: 0.534 | W9: 0.552 | X9: 0.359
C10: 2.369 | D10: 1.994 | E10: 2.861 | F10: 0.424 | G10: 1.908 | H10: 2.013 | I10: 0.516 | J10: 0.089 | L10: 0.604 | M10: 0.567 | N10: 0.128 | O10: 0.326 | Q10: 0.119 | R10: 1.576 | S10: 0.516 | V10: 1.381 | W10: 0.622 | X10: 0.264
C11: 2.803 | D11: 2.397 | E11: 2.41 | F11: 0.089 | G11: 1.855 | H11: 1.257 | I11: 2.028 | J11: 0.48 | L11: 0.67 | M11: 0.16 | N11: 0.303 | O11: 0.675 | Q11: 0.212 | R11: 1.405 | S11: 0.143 | V11: 1.647 | W11: 0.417 | X11: 0.406
C12: 0.548 | D12: 2.419 | E12: 2.888 | F12: 0.292 | G12: 2.549 | H12: 1.963 | I12: 0.319 | L12: 0.558 | M12: 0.565 | O12: 0.148 | Q12: 1.976 | R12: 1.071 | S12: 0.154 | V12: 1.193 | W12: 0.389 | X12: 0.269
C13: 2.148 | D13: 2.373 | E13: 3.319 | F13: 0.241 | G13: 3.707 | H13: 1.927 | I13: 0.262 | L13: 0.545 | M13: 0.611 | Q13: 1.87 | R13: 1.26 | S13: 0.673 | V13: 0.416 | W13: 0.409
C14: 2.155 | D14: 2.494 | E14: 0.712 | F14: 0.234 | G14: 2.648 | H14: 0.937 | I14: 1.406 | L14: 0.739 | M14: 0.466 | Q14: 1.777 | R14: 1.292 | S14: 0.088 | V14: 0.783 | W14: 0.082
C15: 1.946 | D15: 2.403 | E15: 3.154 | F15: 0.185 | G15: 2.215 | H15: 0.362 | I15: 0.728 | L15: 0.553 | M15: 0.649 | Q15: 2.381 | R15: 1.218 | V15: 1.147 | W15: 0.566
C16: 3.258 | D16: 0.232 | E16: 4.162 | F16: 0.27 | G16: 1.703 | H16: 1.561 | I16: 1.051 | L16: 0.338 | M16: 0.571 | Q16: 1.338 | R16: 1.143 | V16: 1.178 | W16: 0.462
B17: 2 | C17: 2.921 | D17: 2.304 | E17: 2.76 | F17: 0.181 | G17: 0.239 | H17: 1.84 | I17: 1.636 | L17: 0.411 | M17: 0.319 | Q17: 3.374 | R17: 1.701 | V17: 0.667 | W17: 0.752
C18: 2.385 | D18: 2.348 | E18: 2.176 | F18: 0.235 | G18: 1.636 | H18: 1.926 | I18: 0.863 | L18: 0.599 | M18: 0.693 | Q18: 1.813 | R18: 1.454 | V18: 0.516 | W18: 0.622
C19: 0.166 | D19: 0.091 | E19: 2.103 | F19: 0.248 | G19: 2.531 | H19: 1.577 | I19: 1.207 | L19: 0.571 | M19: 0.537 | Q19: 3.52 | R19: 0.616 | V19: 0.756 | W19: 0.531
C20: 1.724 | D20: 1.427 | F20: 0.215 | G20: 1.273 | H20: 1.231 | I20: 1.079 | L20: 0.636 | Q20: 2.484 | R20: 1.423 | V20: 0.649 | W20: 0.824
C21: 2.682 | D21: 2.883 | G21: 2.225 | I21: 0.964 | L21: 0.97 | Q21: 3.649 | R21: 1.649 | W21: 0.87
C22: 1.453 | D22: 2.304 | G22: 1.896 | L22: 0.556 | Q22: 2.408 | R22: 0.076 | W22: 0.435
C23: 1.555 | D23: 1.47 | R23: 1.49
C24: 1.728 | D24: 0.364 | R24: 1.838
C25: 2.289 | D25: 1.855 | R25: 1.201
C26: 1.621
B27: Média | C27: =AVERAGE(C7:C26) -> 2.08195 | D27: =AVERAGE(D7:D26) -> 1.9584737 | E27: =AVERAGE(E7:E26) -> 2.7036923 | F27: =AVERAGE(F7:F26) -> 0.23142857 | G27: =AVERAGE(G7:G26) -> 1.785625 | H27: =AVERAGE(H7:H26) -> 1.4884286 | I27: =AVERAGE(I7:I26) -> 1.0623333 | J27: =AVERAGE(J7:J26) -> 0.3048 | ... Z27: =AVERAGE(Z7:Z26) -> #DIV/0!
B28: DP | C28: =STDEV(C7:C26) -> 0.77305351 | D28: =STDEV(D7:D26) -> 0.90057151 | E28: =STDEV(E7:E26) -> 0.81558051 | F28: =STDEV(F7:F26) -> 0.085277569 | G28: =STDEV(G7:G26) -> 0.94718741 | H28: =STDEV(H7:H26) -> 0.64425219 | I28: =STDEV(I7:I26) -> 0.54008011 | J28: =STDEV(J7:J26) -> 0.22382069 | ... Z28: =STDEV(Z7:Z26) -> #DIV/0!
B29: CRR (%) | C29: =C$27/$D$27 -> 1.0630472 | D29: =D$27/$D$27 -> 1 | E29: =E$27/$D$27 -> 1.3805099 | F29: =F$27/$C$27 -> 0.11115952 | G29: =G$27/$C$27 -> 0.85766949 | H29: =H$27/$C$27 -> 0.71492042 | I29: =I$27/$C$27 -> 0.51025881 | J29: =J$27/$C$27 -> 0.14640121 | K29: =K$27/$C$27 -> 0.14169408 | L29: =L$27/$C$27 -> 0.29164365 | M29: =M$27/$C$27 -> 0.25697063 | ... Z29: =Z$27/$C$27 -> #DIV/0!
B30: IER (%) | C30: =(C27-$C$27)/($C$27) -> 0 | D30: =(D27-$C$27)/($C$27) -> -0.059308012 | E30: =(E27-$C$27)/($C$27) -> 0.2986346 | F30: =(F27-$C$27)/($C$27) -> -0.88884048 | G30: =(G27-$C$27)/($C$27) -> -0.14233051 | H30: =(H27-$C$27)/($C$27) -> -0.28507958 | I30: =(I27-$C$27)/($C$27) -> -0.48974119 | J30: =(J27-$C$27)/($C$27) -> -0.85359879 | ... Z30: =(Z27-$C$27)/($C$27) -> #DIV/0!
B32: Tabela de Germinação
B33: Sistema | C33: % | D33: Dupli | E33: Germinação | G33: Média | I33: TG (%) | K33: GRS (%) | M33: CRR (%) | O33: IG (%) | Q33: IGN (%) | S33: IER (%)
B35: Controles | C35: CN - M | D35: 1 | E35: 10 | G35: =AVERAGE(E35:F36) -> 10 | I35: =(G35/10)*100 -> 100 | K35: =(G35/$E$35)*100 -> 100 | M35: =C29 -> 1.0630472 | O35: =(K35*M35)/100 -> 1.0630472 | Q35: =(O35-$O$37)/$O$37 -> 0.11899707 | S35: {=INDEX($C$30:$Z$30, INT((ROW(A1)+1)/2))} -> 0
D36: 2 | E36: 10
C37: CN - T | D37: 1 | E37: 9 | G37: =AVERAGE(E37:F38) -> 9.5 | I37: =(G37/10)*100 -> 95 | K37: =(G37/$E$35)*100 -> 95 | M37: =D29 -> 1 | O37: =(K37*M37)/100 -> 0.95 | Q37: =(O37-$O$37)/$O$37 -> 0 | S37: {=INDEX($C$30:$Z$30, INT((ROW(A3)+1)/2))} -> -0.059308012
D38: 2 | E38: 10
C39: CN - D | D39: 1 | E39: 7 | G39: =AVERAGE(E39:F40) -> 6.5 | I39: =(G39/10)*100 -> 65 | K39: =(G39/$E$35)*100 -> 65 | M39: =E29 -> 1.3805099 | O39: =(K39*M39)/100 -> 0.89733143 | Q39: =(O39-$O$37)/$O$37 -> -0.055440596 | S39: {=INDEX($C$30:$Z$30, INT((ROW(A5)+1)/2))} -> 0.2986346
D40: 2 | E40: 6
C41: CP | D41: 1 | E41: 6 | G41: =AVERAGE(E41:F42) -> 7 | I41: =(G41/10)*100 -> 70 | K41: =(G41/$E$35)*100 -> 70 | M41: =F29 -> 0.11115952 | O41: =(K41*M41)/100 -> 0.077811667 | Q41: =(O41-$O$37)/$O$37 -> -0.91809298 | S41: {=INDEX($C$30:$Z$30, INT((ROW(A7)+1)/2))} -> -0.88884048
D42: 2 | E42: 8
B43: AI | C43: 0 | D43: 1 | E43: 8 | G43: =AVERAGE(E43:F44) -> 8 | I43: =(G43/10)*100 -> 80 | K43: =(G43/$E$35)*100 -> 80 | M43: =G29 -> 0.85766949 | O43: =(K43*M43)/100 -> 0.68613559 | Q43: =(O43-$O$37)/$O$37 -> -0.27775201 | S43: {=INDEX($C$30:$Z$30, INT((ROW(A9)+1)/2))} -> -0.14233051
D44: 2 | E44: 8
...

Sheet Dados prontos Dia 0
B2: Sistema | C2: % | D2: N° de sementes germinadas | E2: TG (%) | F2: GRS (%) | G2: IG (%) | H2: CRR (%) | I2: IGN (%) | J2: IER (%) | L2: >0 | M2: Hormese
L3: 0 a -0,25 | M3: Toxicidade baixa
B4: AI | C4: 0 | D4: ='Dia 0'!G43 -> 8 | E4: =INDIRECT("'Dia 0'!I" & 43 + (ROW(A1)-1)*2) -> 80 | F4: =INDIRECT("'Dia 0'!K" & 43 + (ROW(A1)-1)*2) -> 80 | G4: =INDIRECT("'Dia 0'!O" & 43 + (ROW(A1)-1)*2) -> 0.68613559 | H4: =INDIRECT("'Dia 0'!M" & 43 + (ROW(A1)-1)*2) -> 0.85766949 | I4: =INDIRECT("'Dia 0'!Q" & 43 + (ROW(A1)-1)*2) -> -0.27775201 | J4: =INDIRECT("'Dia 0'!S" & 43 + (ROW(A1)-1)*2) -> -0.14233051 | L4: -0,25 a -0,5 | M4: Toxicidade moderada
C5: 25 | D5: ='Dia 0'!G45 -> 7 | E5: =INDIRECT("'Dia 0'!I" & 43 + (ROW(A2)-1)*2) -> 70 | F5: =INDIRECT("'Dia 0'!K" & 43 + (ROW(A2)-1)*2) -> 70 | G5: =INDIRECT("'Dia 0'!O" & 43 + (ROW(A2)-1)*2) -> 0.50044429 | H5: =INDIRECT("'Dia 0'!M" & 43 + (ROW(A2)-1)*2) -> 0.71492042 | I5: =INDIRECT("'Dia 0'!Q" & 43 + (ROW(A2)-1)*2) -> -0.47321653 | J5: =INDIRECT("'Dia 0'!S" & 43 + (ROW(A2)-1)*2) -> -0.28507958 | L5: -0,5 a -0,75 | M5: Toxicidade alta
C6: 50 | D6: ='Dia 0'!G47 -> 7.5 | E6: =INDIRECT("'Dia 0'!I" & 43 + (ROW(A3)-1)*2) -> 75 | F6: =INDIRECT("'Dia 0'!K" & 43 + (ROW(A3)-1)*2) -> 75 | G6: =INDIRECT("'Dia 0'!O" & 43 + (ROW(A3)-1)*2) -> 0.38269411 | H6: =INDIRECT("'Dia 0'!M" & 43 + (ROW(A3)-1)*2) -> 0.51025881 | I6: =INDIRECT("'Dia 0'!Q" & 43 + (ROW(A3)-1)*2) -> -0.5971641 | J6: =INDIRECT("'Dia 0'!S" & 43 + (ROW(A3)-1)*2) -> -0.48974119 | L6: -0,75 a -1,0 | M6: Toxicidade muito alta
C7: 75 | D7: ='Dia 0'!G49 -> 2.5 | E7: =INDIRECT("'Dia 0'!I" & 43 + (ROW(A4)-1)*2) -> 25 | F7: =INDIRECT("'Dia 0'!K" & 43 + (ROW(A4)-1)*2) -> 25 | G7: =INDIRECT("'Dia 0'!O" & 43 + (ROW(A4)-1)*2) -> 0.036600303 | H7: =INDIRECT("'Dia 0'!M" & 43 + (ROW(A4)-1)*2) -> 0.14640121 | I7: =INDIRECT("'Dia 0'!Q" & 43 + (ROW(A4)-1)*2) -> -0.96147337 | J7: =INDIRECT("'Dia 0'!S" & 43 + (ROW(A4)-1)*2) -> -0.85359879
A8: 100 | C8: 100 | D8: ='Dia 0'!G51 -> 1 | E8: =INDIRECT("'Dia 0'!I" & 43 + (ROW(A5)-1)*2) -> 10 | F8: =INDIRECT("'Dia 0'!K" & 43 + (ROW(A5)-1)*2) -> 10 | G8: =INDIRECT("'Dia 0'!O" & 43 + (ROW(A5)-1)*2) -> 0.014169408 | H8: =INDIRECT("'Dia 0'!M" & 43 + (ROW(A5)-1)*2) -> 0.14169408 | I8: =INDIRECT("'Dia 0'!Q" & 43 + (ROW(A5)-1)*2) -> -0.98508483 | J8: =INDIRECT("'Dia 0'!S" & 43 + (ROW(A5)-1)*2) -> -0.85830592 | L8: TG | M8: Taxa de germinação
B9: A | C9: 0 | D9: ='Dia 0'!G53 -> 8 | E9: =INDIRECT("'Dia 0'!I" & 43 + (ROW(A6)-1)*2) -> 80 | F9: =INDIRECT("'Dia 0'!K" & 43 + (ROW(A6)-1)*2) -> 80 | G9: =INDIRECT("'Dia 0'!O" & 43 + (ROW(A6)-1)*2) -> 0.23331492 | H9: =INDIRECT("'Dia 0'!M" & 43 + (ROW(A6)-1)*2) -> 0.29164365 | I9: =INDIRECT("'Dia 0'!Q" & 43 + (ROW(A6)-1)*2) -> -0.75440535 | J9: =INDIRECT("'Dia 0'!S" & 43 + (ROW(A6)-1)*2) -> -0.70835635 | L9: GRS | M9: Germinação relativa das sementes
C10: 25 | D10: ='Dia 0'!G55 -> 6.5 | E10: =INDIRECT("'Dia 0'!I" & 43 + (ROW(A7)-1)*2) -> 65 | F10: =INDIRECT("'Dia 0'!K" & 43 + (ROW(A7)-1)*2) -> 65 | G10: =INDIRECT("'Dia 0'!O" & 43 + (ROW(A7)-1)*2) -> 0.16703091 | H10: =INDIRECT("'Dia 0'!M" & 43 + (ROW(A7)-1)*2) -> 0.25697063 | I10: =INDIRECT("'Dia 0'!Q" & 43 + (ROW(A7)-1)*2) -> -0.82417799 | J10: =INDIRECT("'Dia 0'!S" & 43 + (ROW(A7)-1)*2) -> -0.74302937 | L10: IG | M10: Índice de germinação
C11: 50 | D11: ='Dia 0'!G57 -> 2.5 | E11: =INDIRECT("'Dia 0'!I" & 43 + (ROW(A8)-1)*2) -> 25 | F11: =INDIRECT("'Dia 0'!K" & 43 + (ROW(A8)-1)*2) -> 25 | G11: =INDIRECT("'Dia 0'!O" & 43 + (ROW(A8)-1)*2) -> 0.024664377 | H11: =INDIRECT("'Dia 0'!M" & 43 + (ROW(A8)-1)*2) -> 0.098657509 | I11: =INDIRECT("'Dia 0'!Q" & 43 + (ROW(A8)-1)*2) -> -0.9740375 | J11: =INDIRECT("'Dia 0'!S" & 43 + (ROW(A8)-1)*2) -> -0.90134249 | L11: CRR | M11: Crescimento relativo da radícula
C12: 75 | D12: ='Dia 0'!G59 -> #DIV/0! | E12: =INDIRECT("'Dia 0'!I" & 43 + (ROW(A9)-1)*2) -> #DIV/0! | F12: =INDIRECT("'Dia 0'!K" & 43 + (ROW(A9)-1)*2) -> #DIV/0! | G12: =INDIRECT("'Dia 0'!O" & 43 + (ROW(A9)-1)*2) -> #DIV/0! | H12: =INDIRECT("'Dia 0'!M" & 43 + (ROW(A9)-1)*2) -> 0.14257467 | I12: =INDIRECT("'Dia 0'!Q" & 43 + (ROW(A9)-1)*2) -> #DIV/0! | J12: =INDIRECT("'Dia 0'!S" & 43 + (ROW(A9)-1)*2) -> -0.85742533 | L12: IGN | M12: Índice de germinação residual normalizado
C13: 100 | D13: ='Dia 0'!G61 -> #DIV/0! | E13: =INDIRECT("'Dia 0'!I" & 43 + (ROW(A10)-1)*2) -> #DIV/0! | F13: =INDIRECT("'Dia 0'!K" & 43 + (ROW(A10)-1)*2) -> #DIV/0! | G13: =INDIRECT("'Dia 0'!O" & 43 + (ROW(A10)-1)*2) -> #DIV/0! | H13: =INDIRECT("'Dia 0'!M" & 43 + (ROW(A10)-1)*2) -> #DIV/0! | I13: =INDIRECT("'Dia 0'!Q" & 43 + (ROW(A10)-1)*2) -> #DIV/0! | J13: =INDIRECT("'Dia 0'!S" & 43 + (ROW(A10)-1)*2) -> #DIV/0! | L13: IER | M13: Índice de alongamento radical residual normalizado
B14: BI | C14: 0 | D14: ='Dia 0'!G63 -> 8 | E14: =INDIRECT("'Dia 0'!I" & 43 + (ROW(A11)-1)*2) -> 80 | F14: =INDIRECT("'Dia 0'!K" & 43 + (ROW(A11)-1)*2) -> 80 | G14: =INDIRECT("'Dia 0'!O" & 43 + (ROW(A11)-1)*2) -> 0.8004515 | H14: =INDIRECT("'Dia 0'!M" & 43 + (ROW(A11)-1)*2) -> 1.0005644 | I14: =INDIRECT("'Dia 0'!Q" & 43 + (ROW(A11)-1)*2) -> -0.15741947 | J14: =INDIRECT("'Dia 0'!S" & 43 + (ROW(A11)-1)*2) -> 0.00056437474
C15: 25 | D15: ='Dia 0'!G65 -> 9.5 | E15: =INDIRECT("'Dia 0'!I" & 43 + (ROW(A12)-1)*2) -> 95 | F15: =INDIRECT("'Dia 0'!K" & 43 + (ROW(A12)-1)*2) -> 95 | G15: =INDIRECT("'Dia 0'!O" & 43 + (ROW(A12)-1)*2) -> 0.56898581 | H15: =INDIRECT("'Dia 0'!M" & 43 + (ROW(A12)-1)*2) -> 0.59893243 | I15: =INDIRECT("'Dia 0'!Q" & 43 + (ROW(A12)-1)*2) -> -0.40106757 | J15: =INDIRECT("'Dia 0'!S" & 43 + (ROW(A12)-1)*2) -> -0.40106757
C16: 50 | D16: ='Dia 0'!G67 -> 4 | E16: =INDIRECT("'Dia 0'!I" & 43 + (ROW(A13)-1)*2) -> 40 | F16: =INDIRECT("'Dia 0'!K" & 43 + (ROW(A13)-1)*2) -> 40 | G16: =INDIRECT("'Dia 0'!O" & 43 + (ROW(A13)-1)*2) -> 0.079732943 | H16: =INDIRECT("'Dia 0'!M" & 43 + (ROW(A13)-1)*2) -> 0.19933236 | I16: =INDIRECT("'Dia 0'!Q" & 43 + (ROW(A13)-1)*2) -> -0.91607059 | J16: =INDIRECT("'Dia 0'!S" & 43 + (ROW(A13)-1)*2) -> -0.80066764
C17: 75 | D17: ='Dia 0'!G69 -> 3 | E17: =INDIRECT("'Dia 0'!I" & 43 + (ROW(A14)-1)*2) -> 30 | F17: =INDIRECT("'Dia 0'!K" & 43 + (ROW(A14)-1)*2) -> 30 | G17: =INDIRECT("'Dia 0'!O" & 43 + (ROW(A14)-1)*2) -> #DIV/0! | H17: =INDIRECT("'Dia 0'!M" & 43 + (ROW(A14)-1)*2) -> #DIV/0! | I17: =INDIRECT("'Dia 0'!Q" & 43 + (ROW(A14)-1)*2) -> #DIV/0! | J17: =INDIRECT("'Dia 0'!S" & 43 + (ROW(A14)-1)*2) -> #DIV/0!
C18: 100 | D18: ='Dia 0'!G71 -> #DIV/0! | E18: =INDIRECT("'Dia 0'!I" & 43 + (ROW(A15)-1)*2) -> #DIV/0! | F18: =INDIRECT("'Dia 0'!K" & 43 + (ROW(A15)-1)*2) -> #DIV/0! | G18: =INDIRECT("'Dia 0'!O" & 43 + (ROW(A15)-1)*2) -> #DIV/0! | H18: =INDIRECT("'Dia 0'!M" & 43 + (ROW(A15)-1)*2) -> #DIV/0! | I18: =INDIRECT("'Dia 0'!Q" & 43 + (ROW(A15)-1)*2) -> #DIV/0! | J18: =INDIRECT("'Dia 0'!S" & 43 + (ROW(A15)-1)*2) -> #DIV/0!
B19: B | C19: 0 | D19: ='Dia 0'!G73 -> 7 | E19: =INDIRECT("'Dia 0'!I" & 43 + (ROW(A16)-1)*2) -> 70 | F19: =INDIRECT("'Dia 0'!K" & 43 + (ROW(A16)-1)*2) -> 70 | G19: =INDIRECT("'Dia 0'!O" & 43 + (ROW(A16)-1)*2) -> 0.30778837 | H19: =INDIRECT("'Dia 0'!M" & 43 + (ROW(A16)-1)*2) -> 0.43969767 | I19: =INDIRECT("'Dia 0'!Q" & 43 + (ROW(A16)-1)*2) -> -0.67601224 | J19: =INDIRECT("'Dia 0'!S" & 43 + (ROW(A16)-1)*2) -> -0.56030233
C20: 25 | D20: ='Dia 0'!G75 -> 8 | E20: =INDIRECT("'Dia 0'!I" & 43 + (ROW(A17)-1)*2) -> 80 | F20: =INDIRECT("'Dia 0'!K" & 43 + (ROW(A17)-1)*2) -> 80 | G20: =INDIRECT("'Dia 0'!O" & 43 + (ROW(A17)-1)*2) -> 0.19265592 | H20: =INDIRECT("'Dia 0'!M" & 43 + (ROW(A17)-1)*2) -> 0.2408199 | I20: =INDIRECT("'Dia 0'!Q" & 43 + (ROW(A17)-1)*2) -> -0.79720429 | J20: =INDIRECT("'Dia 0'!S" & 43 + (ROW(A17)-1)*2) -> -0.7591801
C21: 50 | D21: ='Dia 0'!G77 -> 3 | E21: =INDIRECT("'Dia 0'!I" & 43 + (ROW(A18)-1)*2) -> 30 | F21: =INDIRECT("'Dia 0'!K" & 43 + (ROW(A18)-1)*2) -> 30 | G21: =INDIRECT("'Dia 0'!O" & 43 + (ROW(A18)-1)*2) -> 0.045077932 | H21: =INDIRECT("'Dia 0'!M" & 43 + (ROW(A18)-1)*2) -> 0.15025977 | I21: =INDIRECT("'Dia 0'!Q" & 43 + (ROW(A18)-1)*2) -> -0.95254955 | J21: =INDIRECT("'Dia 0'!S" & 43 + (ROW(A18)-1)*2) -> -0.84974023
C22: 75 | D22: ='Dia 0'!G79 -> 1 | E22: =INDIRECT("'Dia 0'!I" & 43 + (ROW(A19)-1)*2) -> 10 | F22: =INDIRECT("'Dia 0'!K" & 43 + (ROW(A19)-1)*2) -> 10 | G22: =INDIRECT("'Dia 0'!O" & 43 + (ROW(A19)-1)*2) -> 0.0035063282 | H22: =INDIRECT("'Dia 0'!M" & 43 + (ROW(A19)-1)*2) -> 0.035063282 | I22: =INDIRECT("'Dia 0'!Q" & 43 + (ROW(A19)-1)*2) -> -0.99630913 | J22: =INDIRECT("'Dia 0'!S" & 43 + (ROW(A19)-1)*2) -> -0.96493672
C23: 100 | D23: ='Dia 0'!G81 -> #DIV/0! | E23: =INDIRECT("'Dia 0'!I" & 43 + (ROW(A20)-1)*2) -> #DIV/0! | F23: =INDIRECT("'Dia 0'!K" & 43 + (ROW(A20)-1)*2) -> #DIV/0! | G23: =INDIRECT("'Dia 0'!O" & 43 + (ROW(A20)-1)*2) -> #DIV/0! | H23: =INDIRECT("'Dia 0'!M" & 43 + (ROW(A20)-1)*2) -> #DIV/0! | I23: =INDIRECT("'Dia 0'!Q" & 43 + (ROW(A20)-1)*2) -> #DIV/0! | J23: =INDIRECT("'Dia 0'!S" & 43 + (ROW(A20)-1)*2) -> #DIV/0!
B24: CN | D24: ='Dia 0'!G35 -> 10 | E24: ='Dia 0'!I35 -> 100 | F24: ='Dia 0'!K35 -> 100 | G24: ='Dia 0'!O35 -> 1.0630472 | H24: ='Dia 0'!M35 -> 1.0630472 | I24: ='Dia 0'!Q37 -> 0 | J24: ='Dia 0'!S37 -> -0.059308012
B25: CP | D25: ='Dia 0'!G41 -> 7 | E25: ='Dia 0'!I41 -> 70 | F25: ='Dia 0'!K41 -> 70 | G25: ='Dia 0'!O41 -> 0.077811667 | H25: ='Dia 0'!M41 -> 0.11115952 | I25: ='Dia 0'!Q41 -> -0.91809298 | J25: ='Dia 0'!S41 -> -0.88884048

Sheet Dia 7
B2: Tabela de Crescimento Radicular
B3: Tamanho (cm)
B4: Duplicata | C4: Controles | G4: AI | L4: A | Q4: BI | V4: B
C5: CN - M | D5: CN - T | E5: CN - D | F5: CP | G5: 0% | H5: 25% | I5: 50% | J5: 0.75 | K5: 1 | L5: 0% | M5: 25% | N5: 50% | O5: 0.75 | P5: 1 | Q5: 0% | R5: 25% | S5: 50% | T5: 0.75 | U5: 1 | V5: 0% | W5: 25% | X5: 50% | Y5: 0.75 | Z5: 1
B7: 1 | C7: 0.959 | D7: 0.647 | E7: 1.211 | F7: 0.272 | G7: 1.161 | H7: 1.334 | I7: 1.159 | J7: 0.55 | K7: 0.758 | L7: 1.129 | M7: 1.084 | N7: 0.751 | O7: 0.783 | P7: 0.399 | Q7: 1.225 | R7: 1.183 | S7: 0.808 | T7: 0.203 | U7: 0.137 | V7: 0.753 | W7: 1.362 | X7: 1.293 | Y7: 0.496 | Z7: 0.541
C8: 0.89 | D8: 0.742 | E8: 0.886 | F8: 0.348 | G8: 1.224 | H8: 1.909 | I8: 1.233 | J8: 0.72 | K8: 0.187 | L8: 1.953 | M8: 1.214 | N8: 1.489 | O8: 0.56 | P8: 0.107 | Q8: 2.274 | R8: 1.585 | S8: 1.008 | T8: 0.974 | V8: 1.482 | W8: 1.964 | X8: 1.051 | Y8: 0.492 | Z8: 0.256
C9: 0.598 | D9: 0.581 | E9: 1.613 | F9: 0.327 | G9: 0.871 | H9: 1.242 | I9: 1.107 | J9: 0.798 | K9: 0.414 | L9: 1.416 | M9: 1.463 | N9: 1.075 | O9: 0.916 | P9: 0.421 | Q9: 0.858 | R9: 1.264 | S9: 0.789 | T9: 0.528 | V9: 1.779 | W9: 1.573 | X9: 0.057 | Y9: 0.482
C10: 0.649 | D10: 0.465 | E10: 1.035 | F10: 0.407 | G10: 0.997 | H10: 1.168 | I10: 1.017 | J10: 0.875 | K10: 0.364 | L10: 0.482 | M10: 0.975 | N10: 0.786 | O10: 0.086 | P10: 0.482 | Q10: 1.429 | R10: 1.209 | S10: 1.114 | T10: 0.386 | V10: 1.672 | W10: 1.765 | X10: 1.511 | Y10: 0.153
C11: 0.986 | D11: 0.835 | E11: 0.49 | F11: 0.265 | G11: 1.449 | H11: 1.621 | I11: 0.977 | J11: 0.894 | K11: 0.102 | L11: 1.695 | M11: 1.385 | N11: 0.878 | Q11: 1.6 | R11: 1.538 | S11: 1.063 | T11: 0.168 | V11: 0.31 | W11: 0.987 | X11: 0.421
C12: 0.994 | D12: 0.342 | E12: 1.045 | F12: 0.385 | G12: 1.389 | H12: 1.596 | I12: 0.721 | J12: 0.724 | L12: 1.446 | M12: 1.077 | N12: 0.254 | Q12: 1.064 | R12: 1.634 | S12: 1.202 | T12: 0.622 | V12: 1.44 | W12: 2.255 | X12: 1.118
C13: 0.866 | D13: 1.224 | E13: 1.066 | F13: 0.287 | G13: 1.075 | H13: 1.286 | I13: 1.208 | J13: 0.679 | L13: 1.411 | M13: 1.502 | N13: 0.88 | Q13: 1.449 | R13: 0.315 | S13: 0.682 | V13: 1.842 | W13: 1.478 | X13: 0.844
C14: 0.657 | D14: 0.988 | E14: 1.362 | F14: 0.264 | G14: 1.166 | H14: 1.11 | I14: 1.422 | J14: 0.325 | L14: 0.874 | M14: 1.238 | N14: 0.949 | Q14: 0.804 | R14: 0.477 | S14: 1.114 | V14: 1.778 | W14: 1.478 | X14: 0.809
C15: 0.722 | D15: 1.534 | E15: 0.863 | F15: 0.325 | G15: 2.076 | H15: 1.472 | I15: 1.051 | J15: 0.563 | L15: 1.351 | M15: 1.058 | N15: 0.494 | Q15: 1.541 | R15: 1.809 | S15: 1.251 | V15: 2.087 | W15: 0.833 | X15: 0.835
C16: 0.505 | D16: 0.656 | E16: 1.074 | F16: 0.284 | G16: 0.835 | H16: 1.441 | I16: 0.655 | J16: 0.797 | L16: 1.504 | M16: 0.792 | N16: 0.902 | Q16: 0.774 | R16: 0.88 | S16: 0.507 | V16: 1.323 | W16: 0.247 | X16: 0.327
B17: 2 | C17: 1.001 | D17: 1.286 | E17: 1.909 | F17: 0.207 | G17: 1.196 | H17: 1.275 | I17: 0.877 | J17: 0.306 | L17: 1.132 | M17: 1.499 | N17: 0.677 | Q17: 1.478 | R17: 1.062 | S17: 1.488 | V17: 1.153 | W17: 0.816 | X17: 0.48
C18: 0.971 | D18: 0.595 | E18: 1.422 | F18: 0.283 | G18: 1.712 | H18: 0.783 | I18: 0.441 | J18: 0.44 | L18: 1.114 | M18: 1.731 | N18: 0.552 | Q18: 1.418 | R18: 1.409 | S18: 0.86 | V18: 0.995 | W18: 1.495 | X18: 0.598
C19: 0.497 | D19: 1.098 | E19: 1.485 | G19: 1.252 | H19: 1.335 | I19: 0.746 | J19: 0.124 | M19: 2.271 | N19: 0.68 | Q19: 0.163 | R19: 1.322 | S19: 0.658 | V19: 1.025 | W19: 1.122 | X19: 1.102
C20: 0.699 | D20: 1.351 | E20: 1.565 | G20: 1.613 | H20: 1.847 | I20: 1.129 | M20: 1.101 | N20: 0.512 | R20: 1.253 | V20: 1.275 | W20: 1.624
C21: 0.496 | D21: 1.156 | E21: 1.17 | H21: 1.411 | I21: 1.26 | M21: 0.825 | N21: 0.918 | R21: 1.203 | V21: 1.51 | W21: 1.109
C22: 1.573 | D22: 0.729 | E22: 1.632 | H22: 1.319 | I22: 0.932 | M22: 1.599 | V22: 1.268 | W22: 1.81
C23: 1.34 | E23: 1.006 | V23: 1.523
C24: 0.799 | E24: 0.688 | V24: 1.998
B27: Média | C27: =AVERAGE(C7:C26) -> 0.84455556 | D27: =AVERAGE(D7:D26) -> 0.8893125 | E27: =AVERAGE(E7:E26) -> 1.1956667 | F27: =AVERAGE(F7:F26) -> 0.3045 | G27: =AVERAGE(G7:G26) -> 1.2868571 | H27: =AVERAGE(H7:H26) -> 1.3843125 | I27: =AVERAGE(I7:I26) -> 0.9959375 | J27: =AVERAGE(J7:J26) -> 0.59961538 | ... Z27: =AVERAGE(Z7:Z26) -> 0.3985
B28: DP | C28: =STDEV(C7:C26) -> 0.28744273 | D28: =STDEV(D7:D26) -> 0.35093546 | E28: =STDEV(E7:E26) -> 0.36393778 | F28: =STDEV(F7:F26) -> 0.056211451 | G28: =STDEV(G7:G26) -> 0.3392827 | H28: =STDEV(H7:H26) -> 0.27526175 | I28: =STDEV(I7:I26) -> 0.25734269 | J28: =STDEV(J7:J26) -> 0.24051942 | ... Z28: =STDEV(Z7:Z26) -> 0.20152543
B29: CRR (%) | C29: =C$27/$C$27 -> 1 | D29: =D$27/$C$27 -> 1.0529947 | E29: =E$27/$E$27 -> 1 | F29: =F$27/$E$27 -> 0.25466964 | G29: =G$27/$E$27 -> 1.0762675 | H29: =H$27/$E$27 -> 1.1577746 | I29: =I$27/$E$27 -> 0.83295581 | J29: =J$27/$E$27 -> 0.50149042 | K29: =K$27/$E$27 -> 0.30526903 | L29: =L$27/$E$27 -> 1.0807778 | ... Z29: =Z$27/$E$27 -> 0.33328687
B30: IER (%) | C30: =(C27-$C$27)/($C$27) -> 0 | D30: =(D27-$C$27)/($C$27) -> 0.052994672 | E30: =(E27-$E$27)/($E$27) -> 0 | F30: =(F27-$E$27)/($E$27) -> -0.74533036 | G30: =(G27-$E$27)/($E$27) -> 0.076267474 | H30: =(H27-$E$27)/($E$27) -> 0.1577746 | I30: =(I27-$E$27)/($E$27) -> -0.16704419 | J30: =(J27-$E$27)/($E$27) -> -0.49850958 | K30: =(K27-$E$27)/($E$27) -> -0.69473097 | L30: =(L27-$E$27)/($E$27) -> 0.080777809 | ... Z30: =(Z27-$E$27)/($E$27) -> -0.66671313
B32: Tabela de Germinação
B33: Sistema | C33: % | D33: Dupli | E33: Germinação | G33: Média | I33: TG (%) | K33: GRS (%) | M33: CRR (%) | O33: IG (%) | Q33: IGN (%) | S33: IER (%)
B35: Controles | C35: CN - M | D35: 1 | E35: 10 | G35: =AVERAGE(E35:F36) -> 9 | I35: =(G35/10)*100 -> 90 | K35: =(G35/$E$35)*100 -> 90 | M35: =C29 -> 1 | O35: =(K35*M35)/100 -> 0.9 | Q35: =(O35-$O$35)/$O$35 -> 0 | S35: {=INDEX($C$30:$Z$30, INT((ROW(A1)+1)/2))} -> 0
D36: 2 | E36: 8
C37: CN - T | D37: 1 | E37: 10 | G37: =AVERAGE(E37:F38) -> 8 | I37: =(G37/10)*100 -> 80 | K37: =(G37/$E$35)*100 -> 80 | M37: =D29 -> 1.0529947 | O37: =(K37*M37)/100 -> 0.84239574 | Q37: =(O37-$O$35)/$O$35 -> -0.064004736 | S37: {=INDEX($C$30:$Z$30, INT((ROW(A3)+1)/2))} -> 0.052994672
D38: 2 | E38: 6
C39: CN - D | D39: 1 | E39: 10 | G39: =AVERAGE(E39:F40) -> 9 | I39: =(G39/10)*100 -> 90 | K39: =(G39/$E$39)*100 -> 90 | M39: =E29 -> 1 | O39: =(K39*M39)/100 -> 0.9 | Q39: =(O39-$O$39)/$O$39 -> 0 | S39: {=INDEX($C$30:$Z$30, INT((ROW(A5)+1)/2))} -> 0
D40: 2 | E40: 8
C41: CP | D41: 1 | E41: 7 | G41: =AVERAGE(E41:F42) -> 6 | I41: =(G41/10)*100 -> 60 | K41: =(G41/$E$39)*100 -> 60 | M41: =F29 -> 0.25466964 | O41: =(K41*M41)/100 -> 0.15280178 | Q41: =(O41-$O$39)/$O$39 -> -0.83022024 | S41: {=INDEX($C$30:$Z$30, INT((ROW(A7)+1)/2))} -> -0.74533036
D42: 2 | E42: 5
B43: AI | C43: 0 | D43: 1 | E43: 4 | G43: =AVERAGE(E43:F44) -> 7 | I43: =(G43/10)*100 -> 70 | K43: =(G43/$E$39)*100 -> 70 | M43: =G29 -> 1.0762675 | O43: =(K43*M43)/100 -> 0.75338723 | Q43: =(O43-$O$39)/$O$39 -> -0.16290308 | S43: {=INDEX($C$30:$Z$30, INT((ROW(A9)+1)/2))} -> 0.076267474
D44: 2 | E44: 10
C45: 25 | D45: 1 | E45: 7 | G45: =AVERAGE(E45:F46) -> 8 | I45: =(G45/10)*100 -> 80 | K45: =(G45/$E$39)*100 -> 80 | M45: =H29 -> 1.1577746 | O45: =(K45*M45)/100 -> 0.92621968 | Q45: =(O45-$O$39)/$O$39 -> 0.02913298 | S45: {=INDEX($C$30:$Z$30, INT((ROW(A11)+1)/2))} -> 0.1577746
D46: 2 | E46: 9
...

Sheet Dados prontos Dia 7
B2: Sistema | C2: % | D2: N° de sementes germinadas | E2: TG (%) | F2: GRS (%) | G2: IG (%) | H2: CRR (%) | I2: IGN (%) | J2: IER (%) | L2: >0 | M2: Hormese
L3: 0 a -0,25 | M3: Toxicidade baixa
B4: AI | C4: 0 | D4: =INDIRECT("'Dia 7'!G" & (43 + (ROW(A1) - 1) * 2)) -> 7 | E4: =INDIRECT("'Dia 7'!I" & 43 + (ROW(A1)-1)*2) -> 70 | F4: =INDIRECT("'Dia 7'!K" & 43 + (ROW(A1)-1)*2) -> 70 | G4: =INDIRECT("'Dia 7'!O" & 43 + (ROW(A1)-1)*2) -> 0.75338723 | H4: =INDIRECT("'Dia 7'!M" & 43 + (ROW(A1)-1)*2) -> 1.0762675 | I4: =INDIRECT("'Dia 7'!Q" & 43 + (ROW(A1)-1)*2) -> -0.16290308 | J4: =INDIRECT("'Dia 7'!S" & 43 + (ROW(A1)-1)*2) -> 0.076267474 | L4: -0,25 a -0,5 | M4: Toxicidade moderada
C5: 25 | D5: =INDIRECT("'Dia 7'!G" & (43 + (ROW(A2) - 1) * 2)) -> 8 | E5: =INDIRECT("'Dia 7'!I" & 43 + (ROW(A2)-1)*2) -> 80 | F5: =INDIRECT("'Dia 7'!K" & 43 + (ROW(A2)-1)*2) -> 80 | G5: =INDIRECT("'Dia 7'!O" & 43 + (ROW(A2)-1)*2) -> 0.92621968 | H5: =INDIRECT("'Dia 7'!M" & 43 + (ROW(A2)-1)*2) -> 1.1577746 | I5: =INDIRECT("'Dia 7'!Q" & 43 + (ROW(A2)-1)*2) -> 0.02913298 | J5: =INDIRECT("'Dia 7'!S" & 43 + (ROW(A2)-1)*2) -> 0.1577746 | L5: -0,5 a -0,75 | M5: Toxicidade alta
C6: 50 | D6: =INDIRECT("'Dia 7'!G" & (43 + (ROW(A3) - 1) * 2)) -> 8 | E6: =INDIRECT("'Dia 7'!I" & 43 + (ROW(A3)-1)*2) -> 80 | F6: =INDIRECT("'Dia 7'!K" & 43 + (ROW(A3)-1)*2) -> 80 | G6: =INDIRECT("'Dia 7'!O" & 43 + (ROW(A3)-1)*2) -> 0.66636465 | H6: =INDIRECT("'Dia 7'!M" & 43 + (ROW(A3)-1)*2) -> 0.83295581 | I6: =INDIRECT("'Dia 7'!Q" & 43 + (ROW(A3)-1)*2) -> -0.25959483 | J6: =INDIRECT("'Dia 7'!S" & 43 + (ROW(A3)-1)*2) -> -0.16704419 | L6: -0,75 a -1,0 | M6: Toxicidade muito alta
C7: 75 | D7: =INDIRECT("'Dia 7'!G" & (43 + (ROW(A4) - 1) * 2)) -> 6.5 | E7: =INDIRECT("'Dia 7'!I" & 43 + (ROW(A4)-1)*2) -> 65 | F7: =INDIRECT("'Dia 7'!K" & 43 + (ROW(A4)-1)*2) -> 65 | G7: =INDIRECT("'Dia 7'!O" & 43 + (ROW(A4)-1)*2) -> 0.32596878 | H7: =INDIRECT("'Dia 7'!M" & 43 + (ROW(A4)-1)*2) -> 0.50149042 | I7: =INDIRECT("'Dia 7'!Q" & 43 + (ROW(A4)-1)*2) -> -0.63781247 | J7: =INDIRECT("'Dia 7'!S" & 43 + (ROW(A4)-1)*2) -> -0.49850958
A8: 100 | C8: 100 | D8: =INDIRECT("'Dia 7'!G" & (43 + (ROW(A5) - 1) * 2)) -> 2.5 | E8: =INDIRECT("'Dia 7'!I" & 43 + (ROW(A5)-1)*2) -> 25 | F8: =INDIRECT("'Dia 7'!K" & 43 + (ROW(A5)-1)*2) -> 25 | G8: =INDIRECT("'Dia 7'!O" & 43 + (ROW(A5)-1)*2) -> 0.076317257 | H8: =INDIRECT("'Dia 7'!M" & 43 + (ROW(A5)-1)*2) -> 0.30526903 | I8: =INDIRECT("'Dia 7'!Q" & 43 + (ROW(A5)-1)*2) -> -0.91520305 | J8: =INDIRECT("'Dia 7'!S" & 43 + (ROW(A5)-1)*2) -> -0.69473097 | L8: TG | M8: Taxa de germinação
B9: A | C9: 0 | D9: =INDIRECT("'Dia 7'!G" & (43 + (ROW(A6) - 1) * 2)) -> 6 | E9: =INDIRECT("'Dia 7'!I" & 43 + (ROW(A6)-1)*2) -> 60 | F9: =INDIRECT("'Dia 7'!K" & 43 + (ROW(A6)-1)*2) -> 60 | G9: =INDIRECT("'Dia 7'!O" & 43 + (ROW(A6)-1)*2) -> 0.64846669 | H9: =INDIRECT("'Dia 7'!M" & 43 + (ROW(A6)-1)*2) -> 1.0807778 | I9: =INDIRECT("'Dia 7'!Q" & 43 + (ROW(A6)-1)*2) -> -0.27948146 | J9: =INDIRECT("'Dia 7'!S" & 43 + (ROW(A6)-1)*2) -> 0.080777809 | L9: GRS | M9: Germinação relativa das sementes
C10: 25 | D10: =INDIRECT("'Dia 7'!G" & (43 + (ROW(A7) - 1) * 2)) -> 8 | E10: =INDIRECT("'Dia 7'!I" & 43 + (ROW(A7)-1)*2) -> 80 | F10: =INDIRECT("'Dia 7'!K" & 43 + (ROW(A7)-1)*2) -> 80 | G10: =INDIRECT("'Dia 7'!O" & 43 + (ROW(A7)-1)*2) -> 0.87039309 | H10: =INDIRECT("'Dia 7'!M" & 43 + (ROW(A7)-1)*2) -> 1.0879914 | I10: =INDIRECT("'Dia 7'!Q" & 43 + (ROW(A7)-1)*2) -> -0.032896571 | J10: =INDIRECT("'Dia 7'!S" & 43 + (ROW(A7)-1)*2) -> 0.087991358 | L10: IG | M10: Índice de germinação
C11: 50 | D11: =INDIRECT("'Dia 7'!G" & (43 + (ROW(A8) - 1) * 2)) -> 7.5 | E11: =INDIRECT("'Dia 7'!I" & 43 + (ROW(A8)-1)*2) -> 75 | F11: =INDIRECT("'Dia 7'!K" & 43 + (ROW(A8)-1)*2) -> 75 | G11: =INDIRECT("'Dia 7'!O" & 43 + (ROW(A8)-1)*2) -> 0.49332311 | H11: =INDIRECT("'Dia 7'!M" & 43 + (ROW(A8)-1)*2) -> 0.65776415 | I11: =INDIRECT("'Dia 7'!Q" & 43 + (ROW(A8)-1)*2) -> -0.45186321 | J11: =INDIRECT("'Dia 7'!S" & 43 + (ROW(A8)-1)*2) -> -0.34223585 | L11: CRR | M11: Crescimento relativo da radícula
C12: 75 | D12: =INDIRECT("'Dia 7'!G" & (43 + (ROW(A9) - 1) * 2)) -> 2 | E12: =INDIRECT("'Dia 7'!I" & 43 + (ROW(A9)-1)*2) -> 20 | F12: =INDIRECT("'Dia 7'!K" & 43 + (ROW(A9)-1)*2) -> 20 | G12: =INDIRECT("'Dia 7'!O" & 43 + (ROW(A9)-1)*2) -> 0.098062448 | H12: =INDIRECT("'Dia 7'!M" & 43 + (ROW(A9)-1)*2) -> 0.49031224 | I12: =INDIRECT("'Dia 7'!Q" & 43 + (ROW(A9)-1)*2) -> -0.89104172 | J12: =INDIRECT("'Dia 7'!S" & 43 + (ROW(A9)-1)*2) -> -0.50968776 | L12: IGN | M12: Índice de germinação residual normalizado
C13: 100 | D13: =INDIRECT("'Dia 7'!G" & (43 + (ROW(A10) - 1) * 2)) -> 2 | E13: =INDIRECT("'Dia 7'!I" & 43 + (ROW(A10)-1)*2) -> 20 | F13: =INDIRECT("'Dia 7'!K" & 43 + (ROW(A10)-1)*2) -> 20 | G13: =INDIRECT("'Dia 7'!O" & 43 + (ROW(A10)-1)*2) -> 0.058921104 | H13: =INDIRECT("'Dia 7'!M" & 43 + (ROW(A10)-1)*2) -> 0.29460552 | I13: =INDIRECT("'Dia 7'!Q" & 43 + (ROW(A10)-1)*2) -> -0.93453211 | J13: =INDIRECT("'Dia 7'!S" & 43 + (ROW(A10)-1)*2) -> -0.70539448 | L13: IER | M13: Índice de alongamento radical residual normalizado
B14: BI | C14: 0 | D14: =INDIRECT("'Dia 7'!G" & (43 + (ROW(A11) - 1) * 2)) -> 6.5 | E14: =INDIRECT("'Dia 7'!I" & 43 + (ROW(A11)-1)*2) -> 65 | F14: =INDIRECT("'Dia 7'!K" & 43 + (ROW(A11)-1)*2) -> 65 | G14: =INDIRECT("'Dia 7'!O" & 43 + (ROW(A11)-1)*2) -> 0.67230276 | H14: =INDIRECT("'Dia 7'!M" & 43 + (ROW(A11)-1)*2) -> 1.0343119 | I14: =INDIRECT("'Dia 7'!Q" & 43 + (ROW(A11)-1)*2) -> -0.25299693 | J14: =INDIRECT("'Dia 7'!S" & 43 + (ROW(A11)-1)*2) -> 0.034311938
C15: 25 | D15: =INDIRECT("'Dia 7'!G" & (43 + (ROW(A12) - 1) * 2)) -> 7.5 | E15: =INDIRECT("'Dia 7'!I" & 43 + (ROW(A12)-1)*2) -> 75 | F15: =INDIRECT("'Dia 7'!K" & 43 + (ROW(A12)-1)*2) -> 75 | G15: =INDIRECT("'Dia 7'!O" & 43 + (ROW(A12)-1)*2) -> 0.75869808 | H15: =INDIRECT("'Dia 7'!M" & 43 + (ROW(A12)-1)*2) -> 1.0115974 | I15: =INDIRECT("'Dia 7'!Q" & 43 + (ROW(A12)-1)*2) -> -0.15700214 | J15: =INDIRECT("'Dia 7'!S" & 43 + (ROW(A12)-1)*2) -> 0.011597435
C16: 50 | D16: =INDIRECT("'Dia 7'!G" & (43 + (ROW(A13) - 1) * 2)) -> 6.5 | E16: =INDIRECT("'Dia 7'!I" & 43 + (ROW(A13)-1)*2) -> 65 | F16: =INDIRECT("'Dia 7'!K" & 43 + (ROW(A13)-1)*2) -> 65 | G16: =INDIRECT("'Dia 7'!O" & 43 + (ROW(A13)-1)*2) -> 0.52456091 | H16: =INDIRECT("'Dia 7'!M" & 43 + (ROW(A13)-1)*2) -> 0.80701679 | I16: =INDIRECT("'Dia 7'!Q" & 43 + (ROW(A13)-1)*2) -> -0.41715454 | J16: =INDIRECT("'Dia 7'!S" & 43 + (ROW(A13)-1)*2) -> -0.19298321
C17: 75 | D17: =INDIRECT("'Dia 7'!G" & (43 + (ROW(A14) - 1) * 2)) -> 3 | E17: =INDIRECT("'Dia 7'!I" & 43 + (ROW(A14)-1)*2) -> 30 | F17: =INDIRECT("'Dia 7'!K" & 43 + (ROW(A14)-1)*2) -> 30 | G17: =INDIRECT("'Dia 7'!O" & 43 + (ROW(A14)-1)*2) -> 0.12047672 | H17: =INDIRECT("'Dia 7'!M" & 43 + (ROW(A14)-1)*2) -> 0.40158907 | I17: =INDIRECT("'Dia 7'!Q" & 43 + (ROW(A14)-1)*2) -> -0.86613698 | J17: =INDIRECT("'Dia 7'!S" & 43 + (ROW(A14)-1)*2) -> -0.59841093
C18: 100 | D18: =INDIRECT("'Dia 7'!G" & (43 + (ROW(A15) - 1) * 2)) -> 1 | E18: =INDIRECT("'Dia 7'!I" & 43 + (ROW(A15)-1)*2) -> 10 | F18: =INDIRECT("'Dia 7'!K" & 43 + (ROW(A15)-1)*2) -> 10 | G18: =INDIRECT("'Dia 7'!O" & 43 + (ROW(A15)-1)*2) -> 0.011458043 | H18: =INDIRECT("'Dia 7'!M" & 43 + (ROW(A15)-1)*2) -> 0.11458043 | I18: =INDIRECT("'Dia 7'!Q" & 43 + (ROW(A15)-1)*2) -> -0.98726884 | J18: =INDIRECT("'Dia 7'!S" & 43 + (ROW(A15)-1)*2) -> -0.88541957
B19: B | C19: 0 | D19: =INDIRECT("'Dia 7'!G" & (43 + (ROW(A16) - 1) * 2)) -> 9 | E19: =INDIRECT("'Dia 7'!I" & 43 + (ROW(A16)-1)*2) -> 90 | F19: =INDIRECT("'Dia 7'!K" & 43 + (ROW(A16)-1)*2) -> 90 | G19: =INDIRECT("'Dia 7'!O" & 43 + (ROW(A16)-1)*2) -> 1.054349 | H19: =INDIRECT("'Dia 7'!M" & 43 + (ROW(A16)-1)*2) -> 1.1714989 | I19: =INDIRECT("'Dia 7'!Q" & 43 + (ROW(A16)-1)*2) -> 0.17149893 | J19: =INDIRECT("'Dia 7'!S" & 43 + (ROW(A16)-1)*2) -> 0.17149893
C20: 25 | D20: =INDIRECT("'Dia 7'!G" & (43 + (ROW(A17) - 1) * 2)) -> 8 | E20: =INDIRECT("'Dia 7'!I" & 43 + (ROW(A17)-1)*2) -> 80 | F20: =INDIRECT("'Dia 7'!K" & 43 + (ROW(A17)-1)*2) -> 80 | G20: =INDIRECT("'Dia 7'!O" & 43 + (ROW(A17)-1)*2) -> 0.9165598 | H20: =INDIRECT("'Dia 7'!M" & 43 + (ROW(A17)-1)*2) -> 1.1456997 | I20: =INDIRECT("'Dia 7'!Q" & 43 + (ROW(A17)-1)*2) -> 0.018399777 | J20: =INDIRECT("'Dia 7'!S" & 43 + (ROW(A17)-1)*2) -> 0.14569975
C21: 50 | D21: =INDIRECT("'Dia 7'!G" & (43 + (ROW(A18) - 1) * 2)) -> 6.5 | E21: =INDIRECT("'Dia 7'!I" & 43 + (ROW(A18)-1)*2) -> 65 | F21: =INDIRECT("'Dia 7'!K" & 43 + (ROW(A18)-1)*2) -> 65 | G21: =INDIRECT("'Dia 7'!O" & 43 + (ROW(A18)-1)*2) -> 0.43682743 | H21: =INDIRECT("'Dia 7'!M" & 43 + (ROW(A18)-1)*2) -> 0.6720422 | I21: =INDIRECT("'Dia 7'!Q" & 43 + (ROW(A18)-1)*2) -> -0.51463619 | J21: =INDIRECT("'Dia 7'!S" & 43 + (ROW(A18)-1)*2) -> -0.3279578
C22: 75 | D22: =INDIRECT("'Dia 7'!G" & (43 + (ROW(A19) - 1) * 2)) -> 2 | E22: =INDIRECT("'Dia 7'!I" & 43 + (ROW(A19)-1)*2) -> 20 | F22: =INDIRECT("'Dia 7'!K" & 43 + (ROW(A19)-1)*2) -> 20 | G22: =INDIRECT("'Dia 7'!O" & 43 + (ROW(A19)-1)*2) -> 0.067870086 | H22: =INDIRECT("'Dia 7'!M" & 43 + (ROW(A19)-1)*2) -> 0.33935043 | I22: =INDIRECT("'Dia 7'!Q" & 43 + (ROW(A19)-1)*2) -> -0.92458879 | J22: =INDIRECT("'Dia 7'!S" & 43 + (ROW(A19)-1)*2) -> -0.66064957
C23: 100 | D23: =INDIRECT("'Dia 7'!G" & (43 + (ROW(A20) - 1) * 2)) -> 1 | E23: =INDIRECT("'Dia 7'!I" & 43 + (ROW(A20)-1)*2) -> 10 | F23: =INDIRECT("'Dia 7'!K" & 43 + (ROW(A20)-1)*2) -> 10 | G23: =INDIRECT("'Dia 7'!O" & 43 + (ROW(A20)-1)*2) -> 0.033328687 | H23: =INDIRECT("'Dia 7'!M" & 43 + (ROW(A20)-1)*2) -> 0.33328687 | I23: =INDIRECT("'Dia 7'!Q" & 43 + (ROW(A20)-1)*2) -> -0.96296813 | J23: =INDIRECT("'Dia 7'!S" & 43 + (ROW(A20)-1)*2) -> -0.66671313
B24: CN | D24: ='Dia 7'!G39 -> 9 | E24: ='Dia 7'!I39 -> 90 | F24: ='Dia 7'!K39 -> 90 | G24: ='Dia 7'!O39 -> 0.9 | H24: ='Dia 7'!M39 -> 1 | I24: ='Dia 7'!Q39 -> 0 | J24: ='Dia 7'!S39 -> 0
B25: CP | D25: ='Dia 7'!G41 -> 6 | E25: ='Dia 7'!I41 -> 60 | F25: ='Dia 7'!K41 -> 60 | G25: ='Dia 7'!O41 -> 0.15280178 | H25: ='Dia 7'!M41 -> 0.25466964 | I25: ='Dia 7'!Q41 -> -0.83022024 | J25: ='Dia 7'!S41 -> -0.74533036

Sheet Dia 14
B2: Tabela de Crescimento Radicular
B3: Tamanho (cm)
B4: Duplicata | C4: Controles | G4: AI | L4: A | Q4: BI | V4: B
C5: CN - M | D5: CN - T | E5: CN - D | F5: CP | G5: 0% | H5: 25% | I5: 50% | J5: 0.75 | K5: 1 | L5: 0% | M5: 25% | N5: 50% | O5: 0.75 | P5: 1 | Q5: 0% | R5: 25% | S5: 50% | T5: 0.75 | U5: 1 | V5: 0% | W5: 25% | X5: 50% | Y5: 0.75 | Z5: 1
B7: 1 | C7: 2.968 | D7: 2.362 | E7: 1.575 | F7: 0.307 | G7: 3.507 | H7: 1.812 | I7: 1.461 | J7: 0.521 | K7: 0.438 | L7: 1.864 | M7: 2.615 | N7: 0.618 | O7: 0.298 | P7: 0.417 | Q7: 0.282 | R7: 1.776 | S7: 1.212 | T7: 0.987 | U7: 0.817 | V7: 2.295 | W7: 2.387 | X7: 1.765 | Y7: 0.697 | Z7: 0.426
C8: 1.807 | D8: 1.859 | E8: 4.9 | F8: 0.143 | G8: 3.422 | H8: 1.25 | I8: 0.693 | J8: 0.585 | K8: 1.228 | L8: 2.576 | M8: 3.534 | N8: 1.61 | O8: 1.483 | P8: 0.51 | Q8: 1.979 | R8: 1.359 | S8: 0.763 | T8: 1.379 | U8: 0.45 | V8: 2.959 | W8: 2.15 | X8: 1.652 | Y8: 1.213 | Z8: 0.505
C9: 1.362 | D9: 4.998 | E9: 1.639 | F9: 0.269 | G9: 3.221 | H9: 1.725 | I9: 1.002 | J9: 0.389 | K9: 0.838 | L9: 3.916 | M9: 3.057 | N9: 1.531 | O9: 1 | P9: 0.47 | Q9: 3.195 | R9: 1.034 | S9: 0.785 | T9: 1.147 | U9: 0.428 | V9: 2.851 | W9: 0.178 | X9: 1.609 | Y9: 0.605 | Z9: 0.644
C10: 3.916 | D10: 3.859 | E10: 1.75 | F10: 0.316 | G10: 3.967 | H10: 2.151 | I10: 1.713 | J10: 0.615 | K10: 0.261 | L10: 3.094 | M10: 1.644 | N10: 1.54 | O10: 0.968 | P10: 0.484 | Q10: 1.879 | R10: 1.375 | S10: 0.811 | T10: 0.843 | U10: 0.556 | V10: 0.692 | W10: 1.848 | X10: 1.638 | Y10: 0.927 | Z10: 0.898
C11: 0.356 | D11: 2.51 | E11: 1.548 | F11: 0.231 | G11: 3.276 | H11: 2.142 | I11: 0.894 | J11: 0.725 | K11: 0.733 | L11: 3.362 | M11: 3.315 | N11: 1.807 | O11: 1.345 | P11: 1.55 | Q11: 2.823 | R11: 1.723 | S11: 1.104 | T11: 1.15 | U11: 0.395 | V11: 3.37 | W11: 2.526 | X11: 1.762 | Y11: 0.744 | Z11: 1.138
C12: 2.918 | D12: 4.713 | E12: 1.859 | F12: 0.188 | G12: 2.213 | H12: 1.687 | I12: 2.126 | J12: 0.96 | K12: 0.651 | L12: 0.181 | M12: 2.524 | N12: 0.112 | O12: 1.762 | P12: 1.21 | Q12: 3.7 | R12: 1.331 | S12: 1.685 | T12: 1.333 | U12: 1.015 | V12: 3.097 | W12: 2.034 | X12: 1.954 | Y12: 1.066 | Z12: 0.794
C13: 0.302 | D13: 4.163 | E13: 4.186 | F13: 0.316 | G13: 3.623 | H13: 1.389 | I13: 1.804 | J13: 0.56 | K13: 0.767 | L13: 2.487 | M13: 2.204 | N13: 1.297 | O13: 1.049 | P13: 0.77 | Q13: 0.088 | R13: 0.891 | S13: 1.077 | T13: 0.924 | U13: 0.602 | V13: 3.564 | W13: 1.894 | X13: 1.49 | Y13: 0.464 | Z13: 0.398
C14: 1.897 | D14: 0.341 | E14: 2.075 | F14: 0.298 | G14: 3.091 | H14: 0.352 | I14: 1.668 | J14: 0.861 | K14: 0.4 | L14: 3.894 | M14: 0.245 | N14: 0.107 | O14: 0.403 | Q14: 2.625 | R14: 1.951 | S14: 1.952 | T14: 1.091 | U14: 0.936 | V14: 3.835 | W14: 5.093 | X14: 1.554 | Y14: 0.945 | Z14: 0.541
C15: 1.913 | D15: 3.777 | E15: 3.358 | F15: 0.252 | G15: 2.441 | H15: 0.742 | I15: 1.515 | J15: 0.927 | L15: 4.888 | M15: 1.095 | N15: 1.409 | O15: 0.429 | Q15: 2.262 | R15: 1.717 | S15: 0.583 | T15: 0.796 | U15: 0.618 | V15: 3.342 | W15: 1.389 | X15: 1.39 | Y15: 1.16 | Z15: 0.198
C16: 3.703 | D16: 2.413 | E16: 0.094 | F16: 0.253 | G16: 2.619 | H16: 1.641 | I16: 1.077 | J16: 0.844 | L16: 0.229 | M16: 1.25 | N16: 0.887 | O16: 1.048 | Q16: 6.014 | R16: 1.94 | S16: 1.451 | T16: 1.071 | U16: 0.496 | V16: 2.082 | W16: 2.031 | X16: 1.409 | Y16: 1.114 | Z16: 0.771
B17: 2 | C17: 0.49 | D17: 1.574 | E17: 1.822 | F17: 0.275 | G17: 3.126 | H17: 1.583 | I17: 0.782 | J17: 2.109 | L17: 3.48 | M17: 0.683 | N17: 0.64 | O17: 0.98 | Q17: 3.074 | R17: 1.7 | S17: 1.54 | T17: 0.997 | U17: 1.092 | V17: 0.276 | W17: 2.259 | X17: 1.326 | Y17: 1.337 | Z17: 0.626
C18: 2.24 | D18: 0.605 | E18: 2.385 | F18: 0.301 | G18: 3.699 | H18: 1.643 | I18: 1.224 | J18: 1.245 | L18: 4.785 | M18: 1.073 | N18: 0.408 | O18: 0.484 | Q18: 2.201 | R18: 2.123 | S18: 0.956 | T18: 0.886 | U18: 0.598 | V18: 1.32 | W18: 1.77 | X18: 1.283 | Y18: 0.733
C19: 3.228 | D19: 2.024 | E19: 3.441 | H19: 1.733 | I19: 0.94 | J19: 0.665 | L19: 3.292 | M19: 1.146 | N19: 0.649 | O19: 1.136 | Q19: 0.533 | R19: 1.96 | S19: 1.528 | T19: 1.408 | U19: 0.741 | V19: 5.233 | W19: 2.586 | X19: 1.267 | Y19: 0.783
C20: 2.22 | D20: 3.689 | E20: 4.053 | H20: 2.188 | J20: 2.203 | L20: 4.635 | M20: 0.66 | N20: 1.025 | O20: 0.998 | Q20: 3.007 | R20: 1.937 | T20: 0.917 | U20: 0.9 | V20: 5.325 | W20: 2.389 | X20: 1.519 | Y20: 1.028
D21: 2.548 | E21: 3.351 | J21: 0.914 | L21: 3.492 | M21: 0.532 | N21: 1.197 | O21: 0.161 | Q21: 0.965 | T21: 0.751 | U21: 0.528 | V21: 4.798 | W21: 2.3 | X21: 1.516
D22: 2.957 | E22: 3.595 | M22: 0.684 | O22: 0.401 | Q22: 3.69 | U22: 0.554 | V22: 3.892 | W22: 1.61 | X22: 1.922
D23: 2.583 | E23: 3.897 | V23: 2.664 | X23: 0.748
D24: 3.183 | E24: 1.389 | V24: 2.923 | X24: 1.397
D25: 1.046
B27: Média | C27: =AVERAGE(C7:C26) -> 2.0942857 | D27: =AVERAGE(D7:D26) -> 2.6949474 | E27: =AVERAGE(E7:E26) -> 2.6065 | F27: =AVERAGE(F7:F26) -> 0.26241667 | G27: =AVERAGE(G7:G26) -> 3.18375 | H27: =AVERAGE(H7:H26) -> 1.5741429 | I27: =AVERAGE(I7:I26) -> 1.2999231 | J27: =AVERAGE(J7:J26) -> 0.94153333 | ... Z27: =AVERAGE(Z7:Z26) -> 0.63081818
B28: DP | C28: =STDEV(C7:C26) -> 1.1822095 | D28: =STDEV(D7:D26) -> 1.3047943 | E28: =STDEV(E7:E26) -> 1.2709433 | F28: =STDEV(F7:F26) -> 0.053656243 | G28: =STDEV(G7:G26) -> 0.52811571 | H28: =STDEV(H7:H26) -> 0.51769338 | I28: =STDEV(I7:I26) -> 0.44627616 | J28: =STDEV(J7:J26) -> 0.53775218 | ... Z28: =STDEV(Z7:Z26) -> 0.26124311
B29: CRR (%) | C29: =C$27/$C$27 -> 1 | D29: =D$27/$C$27 -> 1.2868098 | E29: =E$27/$C$27 -> 1.2445771 | F29: =F$27/$C$27 -> 0.12530127 | G29: =G$27/$C$27 -> 1.520208 | H29: =H$27/$C$27 -> 0.75163711 | I29: =I$27/$C$27 -> 0.62069997 | J29: =J$27/$C$27 -> 0.44957253 | ... Z29: =Z$27/$C$27 -> 0.30120923
B30: IER (%) | C30: =(C27-$C$27)/($C$27) -> 0 | D30: =(D27-$C$27)/($C$27) -> 0.28680979 | E30: =(E27-$C$27)/($C$27) -> 0.24457708 | F30: =(F27-$C$27)/($C$27) -> -0.87469873 | G30: =(G27-$C$27)/($C$27) -> 0.52020805 | H30: =(H27-$C$27)/($C$27) -> -0.24836289 | I30: =(I27-$C$27)/($C$27) -> -0.37930003 | J30: =(J27-$C$27)/($C$27) -> -0.55042747 | ... Z30: =(Z27-$C$27)/($C$27) -> -0.69879077
B32: Tabela de Germinação
B33: Sistema | C33: % | D33: Dupli | E33: Germinação | G33: Média | I33: TG (%) | K33: GRS (%) | M33: CRR (%) | O33: IG (%) | Q33: IGN (%) | S33: IER (%)
B35: Controles | C35: CN - M | D35: 1 | E35: 6 | G35: =AVERAGE(E35:F36) -> 7 | I35: =(G35/10)*100 -> 70 | K35: =(G35/$E$35)*100 -> 116.66667 | M35: =C29 -> 1 | O35: =(K35*M35)/100 -> 1.1666667 | Q35: =(O35-$O$35)/$O$35 -> 0 | S35: {=INDEX($C$30:$Z$30, INT((ROW(A1)+1)/2))} -> 0
D36: 2 | E36: 8
C37: CN - T | D37: 1 | E37: 10 | G37: =AVERAGE(E37:F38) -> 9.5 | I37: =(G37/10)*100 -> 95 | K37: =(G37/$E$35)*100 -> 158.33333 | M37: =D29 -> 1.2868098 | O37: =(K37*M37)/100 -> 2.0374488 | Q37: =(O37-$O$35)/$O$35 -> 0.74638472 | S37: {=INDEX($C$30:$Z$30, INT((ROW(A3)+1)/2))} -> 0.28680979
D38: 2 | E38: 9
C39: CN - D | D39: 1 | E39: 8 | G39: =AVERAGE(E39:F40) -> 9 | I39: =(G39/10)*100 -> 90 | K39: =(G39/$E$35)*100 -> 150 | M39: =E29 -> 1.2445771 | O39: =(K39*M39)/100 -> 1.8668656 | Q39: =(O39-$O$35)/$O$35 -> 0.60017053 | S39: {=INDEX($C$30:$Z$30, INT((ROW(A5)+1)/2))} -> 0.24457708
D40: 2 | E40: 10
C41: CP | D41: 1 | E41: 8 | G41: =AVERAGE(E41:F42) -> 6 | I41: =(G41/10)*100 -> 60 | K41: =(G41/$E$35)*100 -> 100 | M41: =F29 -> 0.12530127 | O41: =(K41*M41)/100 -> 0.12530127 | Q41: =(O41-$O$35)/$O$35 -> -0.89259891 | S41: {=INDEX($C$30:$Z$30, INT((ROW(A7)+1)/2))} -> -0.87469873
D42: 2 | E42: 4
B43: AI | C43: 0 | D43: 1 | E43: 6 | G43: =AVERAGE(E43:F44) -> 6 | I43: =(G43/10)*100 -> 60 | K43: =(G43/$E$35)*100 -> 100 | M43: =G29 -> 1.520208 | O43: =(K43*M43)/100 -> 1.520208 | Q43: =(O43-$O$35)/$O$35 -> 0.30303547 | S43: {=INDEX($C$30:$Z$30, INT((ROW(A9)+1)/2))} -> 0.52020805
D44: 2 | E44: 6
C45: 25 | D45: 1 | E45: 6 | G45: =AVERAGE(E45:F46) -> 7 | I45: =(G45/10)*100 -> 70 | K45: =(G45/$E$35)*100 -> 116.66667 | M45: =H29 -> 0.75163711 | O45: =(K45*M45)/100 -> 0.87690996 | Q45: =(O45-$O$35)/$O$35 -> -0.24836289 | S45: {=INDEX($C$30:$Z$30, INT((ROW(A11)+1)/2))} -> -0.24836289
...

Sheet Dados prontos Dia 14
B2: Sistema | C2: % | D2: N° de sementes germinadas | E2: TG (%) | F2: GRS (%) | G2: IG (%) | H2: CRR (%) | I2: IGN (%) | J2: IER (%) | L2: >0 | M2: Hormese
L3: 0 a -0,25 | M3: Toxicidade baixa
B4: AI | C4: 0 | D4: =INDIRECT("'Dia 14'!G" & (43 + (ROW(A1) - 1) * 2)) -> 6 | E4: =INDIRECT("'Dia 14'!I" & 43 + (ROW(A1)-1)*2) -> 60 | F4: =INDIRECT("'Dia 14'!K" & 43 + (ROW(A1)-1)*2) -> 100 | G4: =INDIRECT("'Dia 14'!O" & 43 + (ROW(A1)-1)*2) -> 1.520208 | H4: =INDIRECT("'Dia 14'!M" & 43 + (ROW(A1)-1)*2) -> 1.520208 | I4: =INDIRECT("'Dia 14'!Q" & 43 + (ROW(A1)-1)*2) -> 0.30303547 | J4: =INDIRECT("'Dia 14'!S" & 43 + (ROW(A1)-1)*2) -> 0.52020805 | L4: -0,25 a -0,5 | M4: Toxicidade moderada
C5: 25 | D5: =INDIRECT("'Dia 14'!G" & (43 + (ROW(A2) - 1) * 2)) -> 7 | E5: =INDIRECT("'Dia 14'!I" & 43 + (ROW(A2)-1)*2) -> 70 | F5: =INDIRECT("'Dia 14'!K" & 43 + (ROW(A2)-1)*2) -> 116.66667 | G5: =INDIRECT("'Dia 14'!O" & 43 + (ROW(A2)-1)*2) -> 0.87690996 | H5: =INDIRECT("'Dia 14'!M" & 43 + (ROW(A2)-1)*2) -> 0.75163711 | I5: =INDIRECT("'Dia 14'!Q" & 43 + (ROW(A2)-1)*2) -> -0.24836289 | J5: =INDIRECT("'Dia 14'!S" & 43 + (ROW(A2)-1)*2) -> -0.24836289 | L5: -0,5 a -0,75 | M5: Toxicidade alta
C6: 50 | D6: =INDIRECT("'Dia 14'!G" & (43 + (ROW(A3) - 1) * 2)) -> 6.5 | E6: =INDIRECT("'Dia 14'!I" & 43 + (ROW(A3)-1)*2) -> 65 | F6: =INDIRECT("'Dia 14'!K" & 43 + (ROW(A3)-1)*2) -> 108.33333 | G6: =INDIRECT("'Dia 14'!O" & 43 + (ROW(A3)-1)*2) -> 0.67242497 | H6: =INDIRECT("'Dia 14'!M" & 43 + (ROW(A3)-1)*2) -> 0.62069997 | I6: =INDIRECT("'Dia 14'!Q" & 43 + (ROW(A3)-1)*2) -> -0.42363574 | J6: =INDIRECT("'Dia 14'!S" & 43 + (ROW(A3)-1)*2) -> -0.37930003 | L6: -0,75 a -1,0 | M6: Toxicidade muito alta
C7: 75 | D7: =INDIRECT("'Dia 14'!G" & (43 + (ROW(A4) - 1) * 2)) -> 7.5 | E7: =INDIRECT("'Dia 14'!I" & 43 + (ROW(A4)-1)*2) -> 75 | F7: =INDIRECT("'Dia 14'!K" & 43 + (ROW(A4)-1)*2) -> 125 | G7: =INDIRECT("'Dia 14'!O" & 43 + (ROW(A4)-1)*2) -> 0.56196567 | H7: =INDIRECT("'Dia 14'!M" & 43 + (ROW(A4)-1)*2) -> 0.44957253 | I7: =INDIRECT("'Dia 14'!Q" & 43 + (ROW(A4)-1)*2) -> -0.51831514 | J7: =INDIRECT("'Dia 14'!S" & 43 + (ROW(A4)-1)*2) -> -0.55042747
A8: 100 | C8: 100 | D8: =INDIRECT("'Dia 14'!G" & (43 + (ROW(A5) - 1) * 2)) -> 4 | E8: =INDIRECT("'Dia 14'!I" & 43 + (ROW(A5)-1)*2) -> 40 | F8: =INDIRECT("'Dia 14'!K" & 43 + (ROW(A5)-1)*2) -> 66.666667 | G8: =INDIRECT("'Dia 14'!O" & 43 + (ROW(A5)-1)*2) -> 0.21152797 | H8: =INDIRECT("'Dia 14'!M" & 43 + (ROW(A5)-1)*2) -> 0.31729195 | I8: =INDIRECT("'Dia 14'!Q" & 43 + (ROW(A5)-1)*2) -> -0.81869031 | J8: =INDIRECT("'Dia 14'!S" & 43 + (ROW(A5)-1)*2) -> -0.68270805 | L8: TG | M8: Taxa de germinação
B9: A | C9: 0 | D9: =INDIRECT("'Dia 14'!G" & (43 + (ROW(A6) - 1) * 2)) -> 7.5 | E9: =INDIRECT("'Dia 14'!I" & 43 + (ROW(A6)-1)*2) -> 75 | F9: =INDIRECT("'Dia 14'!K" & 43 + (ROW(A6)-1)*2) -> 125 | G9: =INDIRECT("'Dia 14'!O" & 43 + (ROW(A6)-1)*2) -> 1.8373408 | H9: =INDIRECT("'Dia 14'!M" & 43 + (ROW(A6)-1)*2) -> 1.4698727 | I9: =INDIRECT("'Dia 14'!Q" & 43 + (ROW(A6)-1)*2) -> 0.57486357 | J9: =INDIRECT("'Dia 14'!S" & 43 + (ROW(A6)-1)*2) -> 0.46987267 | L9: GRS | M9: Germinação relativa das sementes
C10: 25 | D10: =INDIRECT("'Dia 14'!G" & (43 + (ROW(A7) - 1) * 2)) -> 8 | E10: =INDIRECT("'Dia 14'!I" & 43 + (ROW(A7)-1)*2) -> 80 | F10: =INDIRECT("'Dia 14'!K" & 43 + (ROW(A7)-1)*2) -> 133.33333 | G10: =INDIRECT("'Dia 14'!O" & 43 + (ROW(A7)-1)*2) -> 1.0449466 | H10: =INDIRECT("'Dia 14'!M" & 43 + (ROW(A7)-1)*2) -> 0.78370993 | I10: =INDIRECT("'Dia 14'!Q" & 43 + (ROW(A7)-1)*2) -> -0.10433151 | J10: =INDIRECT("'Dia 14'!S" & 43 + (ROW(A7)-1)*2) -> -0.21629007 | L10: IG | M10: Índice de germinação
C11: 50 | D11: =INDIRECT("'Dia 14'!G" & (43 + (ROW(A8) - 1) * 2)) -> 7.5 | E11: =INDIRECT("'Dia 14'!I" & 43 + (ROW(A8)-1)*2) -> 75 | F11: =INDIRECT("'Dia 14'!K" & 43 + (ROW(A8)-1)*2) -> 125 | G11: =INDIRECT("'Dia 14'!O" & 43 + (ROW(A8)-1)*2) -> 0.59037631 | H11: =INDIRECT("'Dia 14'!M" & 43 + (ROW(A8)-1)*2) -> 0.47230105 | I11: =INDIRECT("'Dia 14'!Q" & 43 + (ROW(A8)-1)*2) -> -0.49396317 | J11: =INDIRECT("'Dia 14'!S" & 43 + (ROW(A8)-1)*2) -> -0.52769895 | L11: CRR | M11: Crescimento relativo da radícula
C12: 75 | D12: =INDIRECT("'Dia 14'!G" & (43 + (ROW(A9) - 1) * 2)) -> 8 | E12: =INDIRECT("'Dia 14'!I" & 43 + (ROW(A9)-1)*2) -> 80 | F12: =INDIRECT("'Dia 14'!K" & 43 + (ROW(A9)-1)*2) -> 133.33333 | G12: =INDIRECT("'Dia 14'!O" & 43 + (ROW(A9)-1)*2) -> 0.5548829 | H12: =INDIRECT("'Dia 14'!M" & 43 + (ROW(A9)-1)*2) -> 0.41616218 | I12: =INDIRECT("'Dia 14'!Q" & 43 + (ROW(A9)-1)*2) -> -0.52438608 | J12: =INDIRECT("'Dia 14'!S" & 43 + (ROW(A9)-1)*2) -> -0.58383782 | L12: IGN | M12: Índice de germinação residual normalizado
C13: 100 | D13: =INDIRECT("'Dia 14'!G" & (43 + (ROW(A10) - 1) * 2)) -> 4.5 | E13: =INDIRECT("'Dia 14'!I" & 43 + (ROW(A10)-1)*2) -> 45 | F13: =INDIRECT("'Dia 14'!K" & 43 + (ROW(A10)-1)*2) -> 75 | G13: =INDIRECT("'Dia 14'!O" & 43 + (ROW(A10)-1)*2) -> 0.27682469 | H13: =INDIRECT("'Dia 14'!M" & 43 + (ROW(A10)-1)*2) -> 0.36909959 | I13: =INDIRECT("'Dia 14'!Q" & 43 + (ROW(A10)-1)*2) -> -0.76272169 | J13: =INDIRECT("'Dia 14'!S" & 43 + (ROW(A10)-1)*2) -> -0.63090041 | L13: IER | M13: Índice de alongamento radical residual normalizado
B14: BI | C14: 0 | D14: =INDIRECT("'Dia 14'!G" & (43 + (ROW(A11) - 1) * 2)) -> 8 | E14: =INDIRECT("'Dia 14'!I" & 43 + (ROW(A11)-1)*2) -> 80 | F14: =INDIRECT("'Dia 14'!K" & 43 + (ROW(A11)-1)*2) -> 133.33333 | G14: =INDIRECT("'Dia 14'!O" & 43 + (ROW(A11)-1)*2) -> 1.5246646 | H14: =INDIRECT("'Dia 14'!M" & 43 + (ROW(A11)-1)*2) -> 1.1434985 | I14: =INDIRECT("'Dia 14'!Q" & 43 + (ROW(A11)-1)*2) -> 0.30685539 | J14: =INDIRECT("'Dia 14'!S" & 43 + (ROW(A11)-1)*2) -> 0.14349847
C15: 25 | D15: =INDIRECT("'Dia 14'!G" & (43 + (ROW(A12) - 1) * 2)) -> 7 | E15: =INDIRECT("'Dia 14'!I" & 43 + (ROW(A12)-1)*2) -> 70 | F15: =INDIRECT("'Dia 14'!K" & 43 + (ROW(A12)-1)*2) -> 116.66667 | G15: =INDIRECT("'Dia 14'!O" & 43 + (ROW(A12)-1)*2) -> 0.907907 | H15: =INDIRECT("'Dia 14'!M" & 43 + (ROW(A12)-1)*2) -> 0.778206 | I15: =INDIRECT("'Dia 14'!Q" & 43 + (ROW(A12)-1)*2) -> -0.221794 | J15: =INDIRECT("'Dia 14'!S" & 43 + (ROW(A12)-1)*2) -> -0.221794
C16: 50 | D16: =INDIRECT("'Dia 14'!G" & (43 + (ROW(A13) - 1) * 2)) -> 6.5 | E16: =INDIRECT("'Dia 14'!I" & 43 + (ROW(A13)-1)*2) -> 65 | F16: =INDIRECT("'Dia 14'!K" & 43 + (ROW(A13)-1)*2) -> 108.33333 | G16: =INDIRECT("'Dia 14'!O" & 43 + (ROW(A13)-1)*2) -> 0.6146487 | H16: =INDIRECT("'Dia 14'!M" & 43 + (ROW(A13)-1)*2) -> 0.56736803 | I16: =INDIRECT("'Dia 14'!Q" & 43 + (ROW(A13)-1)*2) -> -0.47315825 | J16: =INDIRECT("'Dia 14'!S" & 43 + (ROW(A13)-1)*2) -> -0.43263197
C17: 75 | D17: =INDIRECT("'Dia 14'!G" & (43 + (ROW(A14) - 1) * 2)) -> 7.5 | E17: =INDIRECT("'Dia 14'!I" & 43 + (ROW(A14)-1)*2) -> 75 | F17: =INDIRECT("'Dia 14'!K" & 43 + (ROW(A14)-1)*2) -> 125 | G17: =INDIRECT("'Dia 14'!O" & 43 + (ROW(A14)-1)*2) -> 0.62391996 | H17: =INDIRECT("'Dia 14'!M" & 43 + (ROW(A14)-1)*2) -> 0.49913597 | I17: =INDIRECT("'Dia 14'!Q" & 43 + (ROW(A14)-1)*2) -> -0.46521146 | J17: =INDIRECT("'Dia 14'!S" & 43 + (ROW(A14)-1)*2) -> -0.50086403
C18: 100 | D18: =INDIRECT("'Dia 14'!G" & (43 + (ROW(A15) - 1) * 2)) -> 8 | E18: =INDIRECT("'Dia 14'!I" & 43 + (ROW(A15)-1)*2) -> 80 | F18: =INDIRECT("'Dia 14'!K" & 43 + (ROW(A15)-1)*2) -> 133.33333 | G18: =INDIRECT("'Dia 14'!O" & 43 + (ROW(A15)-1)*2) -> 0.42679627 | H18: =INDIRECT("'Dia 14'!M" & 43 + (ROW(A15)-1)*2) -> 0.3200972 | I18: =INDIRECT("'Dia 14'!Q" & 43 + (ROW(A15)-1)*2) -> -0.63417462 | J18: =INDIRECT("'Dia 14'!S" & 43 + (ROW(A15)-1)*2) -> -0.6799028
B19: B | C19: 0 | D19: =INDIRECT("'Dia 14'!G" & (43 + (ROW(A16) - 1) * 2)) -> 9 | E19: =INDIRECT("'Dia 14'!I" & 43 + (ROW(A16)-1)*2) -> 90 | F19: =INDIRECT("'Dia 14'!K" & 43 + (ROW(A16)-1)*2) -> 150 | G19: =INDIRECT("'Dia 14'!O" & 43 + (ROW(A16)-1)*2) -> 2.1693156 | H19: =INDIRECT("'Dia 14'!M" & 43 + (ROW(A16)-1)*2) -> 1.4462104 | I19: =INDIRECT("'Dia 14'!Q" & 43 + (ROW(A16)-1)*2) -> 0.85941337 | J19: =INDIRECT("'Dia 14'!S" & 43 + (ROW(A16)-1)*2) -> 0.4462104
C20: 25 | D20: =INDIRECT("'Dia 14'!G" & (43 + (ROW(A17) - 1) * 2)) -> 8 | E20: =INDIRECT("'Dia 14'!I" & 43 + (ROW(A17)-1)*2) -> 80 | F20: =INDIRECT("'Dia 14'!K" & 43 + (ROW(A17)-1)*2) -> 133.33333 | G20: =INDIRECT("'Dia 14'!O" & 43 + (ROW(A17)-1)*2) -> 1.3705548 | H20: =INDIRECT("'Dia 14'!M" & 43 + (ROW(A17)-1)*2) -> 1.0279161 | I20: =INDIRECT("'Dia 14'!Q" & 43 + (ROW(A17)-1)*2) -> 0.17476126 | J20: =INDIRECT("'Dia 14'!S" & 43 + (ROW(A17)-1)*2) -> 0.027916098
C21: 50 | D21: =INDIRECT("'Dia 14'!G" & (43 + (ROW(A18) - 1) * 2)) -> 8.5 | E21: =INDIRECT("'Dia 14'!I" & 43 + (ROW(A18)-1)*2) -> 85 | F21: =INDIRECT("'Dia 14'!K" & 43 + (ROW(A18)-1)*2) -> 141.66667 | G21: =INDIRECT("'Dia 14'!O" & 43 + (ROW(A18)-1)*2) -> 1.0222194 | H21: =INDIRECT("'Dia 14'!M" & 43 + (ROW(A18)-1)*2) -> 0.72156662 | I21: =INDIRECT("'Dia 14'!Q" & 43 + (ROW(A18)-1)*2) -> -0.12381196 | J21: =INDIRECT("'Dia 14'!S" & 43 + (ROW(A18)-1)*2) -> -0.27843338
C22: 75 | D22: =INDIRECT("'Dia 14'!G" & (43 + (ROW(A19) - 1) * 2)) -> 7 | E22: =INDIRECT("'Dia 14'!I" & 43 + (ROW(A19)-1)*2) -> 70 | F22: =INDIRECT("'Dia 14'!K" & 43 + (ROW(A19)-1)*2) -> 116.66667 | G22: =INDIRECT("'Dia 14'!O" & 43 + (ROW(A19)-1)*2) -> 0.50995907 | H22: =INDIRECT("'Dia 14'!M" & 43 + (ROW(A19)-1)*2) -> 0.43710778 | I22: =INDIRECT("'Dia 14'!Q" & 43 + (ROW(A19)-1)*2) -> -0.56289222 | J22: =INDIRECT("'Dia 14'!S" & 43 + (ROW(A19)-1)*2) -> -0.56289222
C23: 100 | D23: =INDIRECT("'Dia 14'!G" & (43 + (ROW(A20) - 1) * 2)) -> 5.5 | E23: =INDIRECT("'Dia 14'!I" & 43 + (ROW(A20)-1)*2) -> 55 | F23: =INDIRECT("'Dia 14'!K" & 43 + (ROW(A20)-1)*2) -> 91.666667 | G23: =INDIRECT("'Dia 14'!O" & 43 + (ROW(A20)-1)*2) -> 0.27610846 | H23: =INDIRECT("'Dia 14'!M" & 43 + (ROW(A20)-1)*2) -> 0.30120923 | I23: =INDIRECT("'Dia 14'!Q" & 43 + (ROW(A20)-1)*2) -> -0.76333561 | J23: =INDIRECT("'Dia 14'!S" & 43 + (ROW(A20)-1)*2) -> -0.69879077
B24: CN | D24: ='Dia 14'!G35 -> 7 | E24: ='Dia 14'!I35 -> 70 | F24: ='Dia 14'!K35 -> 116.66667 | G24: ='Dia 14'!O35 -> 1.1666667 | H24: ='Dia 14'!M35 -> 1 | I24: ='Dia 14'!Q35 -> 0 | J24: ='Dia 14'!S35 -> 0
B25: CP | D25: ='Dia 14'!G41 -> 6 | E25: ='Dia 14'!I41 -> 60 | F25: ='Dia 14'!K41 -> 100 | G25: ='Dia 14'!O41 -> 0.12530127 | H25: ='Dia 14'!M41 -> 0.12530127 | I25: ='Dia 14'!Q41 -> -0.89259891 | J25: ='Dia 14'!S41 -> -0.87469873

Sheet PROCESSAMENTO
B2: TOXICIDADE
B3: Dia 0
B5: % | C5: AI | E5: A | G5: BI | I5: B
C6: IGN (%) | D6: IER (%) | E6: IGN (%) | F6: IER (%) | G6: IGN (%) | H6: IER (%) | I6: IGN (%) | J6: IER (%)
B7: 0 | C7: ='Dados prontos Dia 0'!I4 -> -0.27775201 | D7: ='Dados prontos Dia 0'!J4 -> -0.14233051 | E7: ='Dados prontos Dia 0'!I9 -> -0.75440535 | F7: ='Dados prontos Dia 0'!J9 -> -0.70835635 | G7: ='Dados prontos Dia 0'!I14 -> -0.15741947 | H7: ='Dados prontos Dia 0'!J14 -> 0.00056437474 | I7: ='Dados prontos Dia 0'!I19 -> -0.67601224 | J7: ='Dados prontos Dia 0'!J19 -> -0.56030233
B8: 25 | C8: ='Dados prontos Dia 0'!I5 -> -0.47321653 | D8: ='Dados prontos Dia 0'!J5 -> -0.28507958 | E8: ='Dados prontos Dia 0'!I10 -> -0.82417799 | F8: ='Dados prontos Dia 0'!J10 -> -0.74302937 | G8: ='Dados prontos Dia 0'!I15 -> -0.40106757 | H8: ='Dados prontos Dia 0'!J15 -> -0.40106757 | I8: ='Dados prontos Dia 0'!I20 -> -0.79720429 | J8: ='Dados prontos Dia 0'!J20 -> -0.7591801
B9: 50 | C9: ='Dados prontos Dia 0'!I6 -> -0.5971641 | D9: ='Dados prontos Dia 0'!J6 -> -0.48974119 | E9: ='Dados prontos Dia 0'!I11 -> -0.9740375 | F9: ='Dados prontos Dia 0'!J11 -> -0.90134249 | G9: ='Dados prontos Dia 0'!I16 -> -0.91607059 | H9: ='Dados prontos Dia 0'!J16 -> -0.80066764 | I9: ='Dados prontos Dia 0'!I21 -> -0.95254955 | J9: ='Dados prontos Dia 0'!J21 -> -0.84974023
B10: 75 | C10: ='Dados prontos Dia 0'!I7 -> -0.96147337 | D10: ='Dados prontos Dia 0'!J7 -> -0.85359879 | E10: ='Dados prontos Dia 0'!I12 -> #DIV/0! | F10: ='Dados prontos Dia 0'!J12 -> -0.85742533 | G10: ='Dados prontos Dia 0'!I17 -> #DIV/0! | H10: ='Dados prontos Dia 0'!J17 -> #DIV/0! | I10: ='Dados prontos Dia 0'!I22 -> -0.99630913 | J10: ='Dados prontos Dia 0'!J22 -> -0.96493672
B11: 100 | C11: ='Dados prontos Dia 0'!I8 -> -0.98508483 | D11: ='Dados prontos Dia 0'!J8 -> -0.85830592 | E11: ='Dados prontos Dia 0'!I13 -> #DIV/0! | F11: ='Dados prontos Dia 0'!J13 -> #DIV/0! | G11: ='Dados prontos Dia 0'!I18 -> #DIV/0! | H11: ='Dados prontos Dia 0'!J18 -> #DIV/0! | I11: ='Dados prontos Dia 0'!I23 -> #DIV/0! | J11: ='Dados prontos Dia 0'!J23 -> #DIV/0!
B13: Dia 7
B15: % | C15: AI | E15: A | G15: BI | I15: B
C16: IGN (%) | D16: IER (%) | E16: IGN (%) | F16: IER (%) | G16: IGN (%) | H16: IER (%) | I16: IGN (%) | J16: IER (%)
B17: 0 | C17: ='Dados prontos Dia 7'!I4 -> -0.16290308 | D17: ='Dados prontos Dia 7'!J4 -> 0.076267474 | E17: ='Dados prontos Dia 7'!I9 -> -0.27948146 | F17: ='Dados prontos Dia 7'!J9 -> 0.080777809 | G17: ='Dados prontos Dia 7'!I14 -> -0.25299693 | H17: ='Dados prontos Dia 7'!J14 -> 0.034311938 | I17: ='Dados prontos Dia 7'!I19 -> 0.17149893 | J17: ='Dados prontos Dia 7'!J19 -> 0.17149893
B18: 25 | C18: ='Dados prontos Dia 7'!I5 -> 0.02913298 | D18: ='Dados prontos Dia 7'!J5 -> 0.1577746 | E18: ='Dados prontos Dia 7'!I10 -> -0.032896571 | F18: ='Dados prontos Dia 7'!J10 -> 0.087991358 | G18: ='Dados prontos Dia 7'!I15 -> -0.15700214 | H18: ='Dados prontos Dia 7'!J15 -> 0.011597435 | I18: ='Dados prontos Dia 7'!I20 -> 0.018399777 | J18: ='Dados prontos Dia 7'!J20 -> 0.14569975
B19: 50 | C19: ='Dados prontos Dia 7'!I6 -> -0.25959483 | D19: ='Dados prontos Dia 7'!J6 -> -0.16704419 | E19: ='Dados prontos Dia 7'!I11 -> -0.45186321 | F19: ='Dados prontos Dia 7'!J11 -> -0.34223585 | G19: ='Dados prontos Dia 7'!I16 -> -0.41715454 | H19: ='Dados prontos Dia 7'!J16 -> -0.19298321 | I19: ='Dados prontos Dia 7'!I21 -> -0.51463619 | J19: ='Dados prontos Dia 7'!J21 -> -0.3279578
B20: 75 | C20: ='Dados prontos Dia 7'!I7 -> -0.63781247 | D20: ='Dados prontos Dia 7'!J7 -> -0.49850958 | E20: ='Dados prontos Dia 7'!I12 -> -0.89104172 | F20: ='Dados prontos Dia 7'!J12 -> -0.50968776 | G20: ='Dados prontos Dia 7'!I17 -> -0.86613698 | H20: ='Dados prontos Dia 7'!J17 -> -0.59841093 | I20: ='Dados prontos Dia 7'!I22 -> -0.92458879 | J20: ='Dados prontos Dia 7'!J22 -> -0.66064957
B21: 100 | C21: ='Dados prontos Dia 7'!I8 -> -0.91520305 | D21: ='Dados prontos Dia 7'!J8 -> -0.69473097 | E21: ='Dados prontos Dia 7'!I13 -> -0.93453211 | F21: ='Dados prontos Dia 7'!J13 -> -0.70539448 | G21: ='Dados prontos Dia 7'!I18 -> -0.98726884 | H21: ='Dados prontos Dia 7'!J18 -> -0.88541957 | I21: ='Dados prontos Dia 7'!I23 -> -0.96296813 | J21: ='Dados prontos Dia 7'!J23 -> -0.66671313
B23: Dia 14
B25: % | C25: AI | E25: A | G25: BI | I25: B
C26: IGN (%) | D26: IER (%) | E26: IGN (%) | F26: IER (%) | G26: IGN (%) | H26: IER (%) | I26: IGN (%) | J26: IER (%)
B27: 0 | C27: ='Dados prontos Dia 14'!I4 -> 0.30303547 | D27: ='Dados prontos Dia 14'!J4 -> 0.52020805 | E27: ='Dados prontos Dia 14'!I9 -> 0.57486357 | F27: ='Dados prontos Dia 14'!J9 -> 0.46987267 | G27: ='Dados prontos Dia 14'!I14 -> 0.30685539 | H27: ='Dados prontos Dia 14'!J14 -> 0.14349847 | I27: ='Dados prontos Dia 14'!I19 -> 0.85941337 | J27: ='Dados prontos Dia 14'!J19 -> 0.4462104
B28: 25 | C28: ='Dados prontos Dia 14'!I5 -> -0.24836289 | D28: ='Dados prontos Dia 14'!J5 -> -0.24836289 | E28: ='Dados prontos Dia 14'!I10 -> -0.10433151 | F28: ='Dados prontos Dia 14'!J10 -> -0.21629007 | G28: ='Dados prontos Dia 14'!I15 -> -0.221794 | H28: ='Dados prontos Dia 14'!J15 -> -0.221794 | I28: ='Dados prontos Dia 14'!I20 -> 0.17476126 | J28: ='Dados prontos Dia 14'!J20 -> 0.027916098
B29: 50 | C29: ='Dados prontos Dia 14'!I6 -> -0.42363574 | D29: ='Dados prontos Dia 14'!J6 -> -0.37930003 | E29: ='Dados prontos Dia 14'!I11 -> -0.49396317 | F29: ='Dados prontos Dia 14'!J11 -> -0.52769895 | G29: ='Dados prontos Dia 14'!I16 -> -0.47315825 | H29: ='Dados prontos Dia 14'!J16 -> -0.43263197 | I29: ='Dados prontos Dia 14'!I21 -> -0.12381196 | J29: ='Dados prontos Dia 14'!J21 -> -0.27843338
B30: 75 | C30: ='Dados prontos Dia 14'!I7 -> -0.51831514 | D30: ='Dados prontos Dia 14'!J7 -> -0.55042747 | E30: ='Dados prontos Dia 14'!I12 -> -0.52438608 | F30: ='Dados prontos Dia 14'!J12 -> -0.58383782 | G30: ='Dados prontos Dia 14'!I17 -> -0.46521146 | H30: ='Dados prontos Dia 14'!J17 -> -0.50086403 | I30: ='Dados prontos Dia 14'!I22 -> -0.56289222 | J30: ='Dados prontos Dia 14'!J22 -> -0.56289222
B31: 100 | C31: ='Dados prontos Dia 14'!I8 -> -0.81869031 | D31: ='Dados prontos Dia 14'!J8 -> -0.68270805 | E31: ='Dados prontos Dia 14'!I13 -> -0.76272169 | F31: ='Dados prontos Dia 14'!J13 -> -0.63090041 | G31: ='Dados prontos Dia 14'!I18 -> -0.63417462 | H31: ='Dados prontos Dia 14'!J18 -> -0.6799028 | I31: ='Dados prontos Dia 14'!I23 -> -0.76333561 | J31: ='Dados prontos Dia 14'!J23 -> -0.69879077
